Workbook

Sheet PARCIALES
D1: PARCIAL 1 | M1: PARCIAL 2 | AF1: PARCIAL 3 | AN1: PARCIAL 4 | AT1: GRUPO
A2: Nombre de usuario | B2: Apellidos | C2: Nombre | D2: Encuentre el centro y radio de la circunferencia con ecuación: | E2: Resuelva la desigualdad | F2: Resuelva la desigualdad | G2: Resuelva la desigualdad | H2: Seleccione la ecuación de la circunferencia: | I2: Seleccione la ecuación de la circunferencia: | J2: Simplifique y eliminé exponentes negativos de la siguiente expresión | K2: Simplifique y eliminé exponentes negativos de la siguiente expresión | L2: TOTAL | M2: Encuentre la ecuación de la recta que pasa por (-1,3) y es paralela a la recta 3y-2x-5=0 | N2: Encuentre la ecuación de la recta que pasa por (1,2) y es paralela a la recta x+y=2 | O2: Encuentre la ecuación de la recta que pasa por (1,2) y es perpendicular a la recta x+y=2 | P2: Encuentre la ecuación de la recta que pasa por (-1,3) y es paralela a la recta 2x+y=3 | Q2: Encuentre la ecuación de la recta que pasa por (-1,3) y es perpendicular a la recta 2x+y=3 | R2: La división del polinomio entre el polinomio 2x+1 es: | S2: La división del polinomio entre el polinomio 2x-1 es: | T2: La división del polinomio entre el polinomio x+2 es: | U2: La división del polinomio entre el polinomio x-1 es: | V2: La división del polinomio entre el polinomio x-2 es: | W2: La siguiente función es la función inversa de la función : | X2: La siguiente función es uno o uno (inyectiva): con dominio (-∞,∞) | Y2: La siguiente función es uno o uno (inyectiva): con dominio [-1,∞) | Z2: La siguiente función NO es la función inversa de la función : | AA2: La siguiente función NO es uno o uno (inyectiva): en todo su dominio | AB2: Seleccione un cero (o raíz ) del polinomio | AC2: Seleccione un cero (o raíz) del polinomio | AD2: Seleccione un cero del polinomio | AE2: TOTAL | AF2: Determine la función cuya gráfica es la siguiente: | AG2: Determine la función cuya gráfica es la siguiente: | AH2: Encuentre la solución de la ecuación logarítmica o exponencial | AI2: Encuentre la solución de la ecuación logarítmica o exponencial ln(x)=ln(5)+ln(9) | AJ2: Seleccione el valor exacto de | AK2: Una posible simplifcación de es: | AL2: Una posible simplifcación de es: | AM2: TOTAL | AN2: Encuentre algún valor de x que satisfaga la siguiente ecuación | AO2: Realice la sustición indicada donde y | AP2: Realice la sustición indicada donde , y | AQ2: Seleccione la función cuya gráfica se muestra | AR2: Seleccione una solución de la siguiente ecuación trigonométrica | AS2: TOTAL | AT2: GRUPO
A3: 163701 | B3: Medina Zuñiga | C3: Emilio | D3: =VLOOKUP($A3,'TABLA DINAM PARCIAL 1'!$A$5:$I$793,2,FALSE) -> 0 | E3: =VLOOKUP(A3,'TABLA DINAM PARCIAL 1'!A530:I1318,3,FALSE) -> 0 | F3: =VLOOKUP(A3,'TABLA DINAM PARCIAL 1'!A530:I1318,4,FALSE) -> 0 | G3: =VLOOKUP(A3,'TABLA DINAM PARCIAL 1'!A530:I1318,5,FALSE) -> 0 | H3: =VLOOKUP(A3,'TABLA DINAM PARCIAL 1'!A530:I1318,6,FALSE) -> 0 | I3: =VLOOKUP(A3,'TABLA DINAM PARCIAL 1'!A530:I1318,7,FALSE) -> 0 | J3: =VLOOKUP(A3,'TABLA DINAM PARCIAL 1'!A530:I1318,8,FALSE) -> 0 | K3: =VLOOKUP(A3,'TABLA DINAM PARCIAL 1'!A530:I1318,9,FALSE) -> 0 | L3: =SUM(D3:K3) -> 0 | M3: =VLOOKUP($A3,'TABLA DINAMICA PARCIAL 2'!$A$5:$T$772,2,FALSE) -> 0 | N3: =VLOOKUP($A3,'TABLA DINAMICA PARCIAL 2'!$A$5:$T$772,3,FALSE) -> 0 | O3: =VLOOKUP($A3,'TABLA DINAMICA PARCIAL 2'!$A$5:$T$772,4,FALSE) -> 10 | P3: =VLOOKUP($A3,'TABLA DINAMICA PARCIAL 2'!$A$5:$T$772,5,FALSE) -> 0 | Q3: =VLOOKUP($A3,'TABLA DINAMICA PARCIAL 2'!$A$5:$T$772,6,FALSE) -> 0 | R3: =VLOOKUP($A3,'TABLA DINAMICA PARCIAL 2'!$A$5:$T$772,7,FALSE) -> 0 | S3: =VLOOKUP($A3,'TABLA DINAMICA PARCIAL 2'!$A$5:$T$772,8,FALSE) -> 0 | T3: =VLOOKUP($A3,'TABLA DINAMICA PARCIAL 2'!$A$5:$T$772,9,FALSE) -> 0 | U3: =VLOOKUP($A3,'TABLA DINAMICA PARCIAL 2'!$A$5:$T$772,10,FALSE) -> 0 | V3: =VLOOKUP($A3,'TABLA DINAMICA PARCIAL 2'!$A$5:$T$772,11,FALSE) -> 0 | W3: =VLOOKUP($A3,'TABLA DINAMICA PARCIAL 2'!$A$5:$T$772,12,FALSE) -> 0 | X3: =VLOOKUP($A3,'TABLA DINAMICA PARCIAL 2'!$A$5:$T$772,13,FALSE) -> 0 | Y3: =VLOOKUP($A3,'TABLA DINAMICA PARCIAL 2'!$A$5:$T$772,14,FALSE) -> 0 | Z3: =VLOOKUP($A3,'TABLA DINAMICA PARCIAL 2'!$A$5:$T$772,15,FALSE) -> 0 | AA3: =VLOOKUP($A3,'TABLA DINAMICA PARCIAL 2'!$A$5:$T$772,16,FALSE) -> 0 | AB3: =VLOOKUP(I3,'TABLA DINAMICA PARCIAL 2'!I576:AB1347,17,FALSE) -> 0 | AC3: =VLOOKUP(I3,'TABLA DINAMICA PARCIAL 2'!I576:AB1347,18,FALSE) -> 0 | AD3: =VLOOKUP(I3,'TABLA DINAMICA PARCIAL 2'!I576:AB1347,19,FALSE) -> 0 | AE3: =SUM(M3:AD3) -> 10 | AF3: =VLOOKUP($A3,'TABLA DINAMICA PARCIAL 3'!$A$5:$I$768,2,FALSE) -> 0 | AG3: =VLOOKUP($A3,'TABLA DINAMICA PARCIAL 3'!$A$5:$I$768,3,FALSE) -> 10 | AH3: =VLOOKUP($A3,'TABLA DINAMICA PARCIAL 3'!$A$5:$I$768,4,FALSE) -> 0 | AI3: =VLOOKUP($A3,'TABLA DINAMICA PARCIAL 3'!$A$5:$I$768,5,FALSE) -> 0 | AJ3: =VLOOKUP($A3,'TABLA DINAMICA PARCIAL 3'!$A$5:$I$768,6,FALSE) -> 0 | AK3: =VLOOKUP($A3,'TABLA DINAMICA PARCIAL 3'!$A$5:$I$768,7,FALSE) -> 0 | AL3: =VLOOKUP($A3,'TABLA DINAMICA PARCIAL 3'!$A$5:$I$768,8,FALSE) -> 0 | AM3: =SUM(AF3:AL3) -> 10 | AN3: =VLOOKUP($A3,'TABLA DINAMICA PARCIAL 4'!$A$5:$F$760,2,FALSE) -> 0 | AO3: =VLOOKUP($A3,'TABLA DINAMICA PARCIAL 4'!$A$5:$F$760,3,FALSE) -> 0 | AP3: =VLOOKUP($A3,'TABLA DINAMICA PARCIAL 4'!$A$5:$F$760,4,FALSE) -> 0 | AQ3: =VLOOKUP($A3,'TABLA DINAMICA PARCIAL 4'!$A$5:$F$760,5,FALSE) -> 10 | AR3: =VLOOKUP($A3,'TABLA DINAMICA PARCIAL 4'!$A$5:$F$760,6,FALSE) -> 10 | AS3: =SUM(AN3:AR3) -> 20 | AT3: =VLOOKUP($A3,'USUARIOS Y GRUPO'!$A$2:$D$851,4,FALSE) -> P19-MAT1022-10
A4: 159054 | B4: Rodríguez González | C4: Lisshet | D4: =VLOOKUP($A4,'TABLA DINAM PARCIAL 1'!$A$5:$I$793,2,FALSE) -> 0 | E4: =VLOOKUP($A4,'TABLA DINAM PARCIAL 1'!$A$5:$I$793,3,FALSE) -> 0 | F4: =VLOOKUP($A4,'TABLA DINAM PARCIAL 1'!$A$5:$I$793,4,FALSE) -> 10 | G4: =VLOOKUP($A4,'TABLA DINAM PARCIAL 1'!$A$5:$I$793,5,FALSE) -> 0 | H4: =VLOOKUP($A4,'TABLA DINAM PARCIAL 1'!$A$5:$I$793,6,FALSE) -> 0 | I4: =VLOOKUP($A4,'TABLA DINAM PARCIAL 1'!$A$5:$I$793,7,FALSE) -> 0 | J4: =VLOOKUP($A4,'TABLA DINAM PARCIAL 1'!$A$5:$I$793,8,FALSE) -> 0 | K4: =VLOOKUP($A4,'TABLA DINAM PARCIAL 1'!$A$5:$I$793,9,FALSE) -> 0 | L4: =SUM(D4:K4) -> 10 | M4: =VLOOKUP($A4,'TABLA DINAMICA PARCIAL 2'!$A$5:$T$772,2,FALSE) -> 0 | N4: =VLOOKUP($A4,'TABLA DINAMICA PARCIAL 2'!$A$5:$T$772,3,FALSE) -> 0 | O4: =VLOOKUP($A4,'TABLA DINAMICA PARCIAL 2'!$A$5:$T$772,4,FALSE) -> 0 | P4: =VLOOKUP($A4,'TABLA DINAMICA PARCIAL 2'!$A$5:$T$772,5,FALSE) -> 0 | Q4: =VLOOKUP($A4,'TABLA DINAMICA PARCIAL 2'!$A$5:$T$772,6,FALSE) -> 0 | R4: =VLOOKUP($A4,'TABLA DINAMICA PARCIAL 2'!$A$5:$T$772,7,FALSE) -> 0 | S4: =VLOOKUP($A4,'TABLA DINAMICA PARCIAL 2'!$A$5:$T$772,8,FALSE) -> 0 | T4: =VLOOKUP($A4,'TABLA DINAMICA PARCIAL 2'!$A$5:$T$772,9,FALSE) -> 0 | U4: =VLOOKUP($A4,'TABLA DINAMICA PARCIAL 2'!$A$5:$T$772,10,FALSE) -> 0 | V4: =VLOOKUP($A4,'TABLA DINAMICA PARCIAL 2'!$A$5:$T$772,11,FALSE) -> 0 | W4: =VLOOKUP($A4,'TABLA DINAMICA PARCIAL 2'!$A$5:$T$772,12,FALSE) -> 0 | X4: =VLOOKUP($A4,'TABLA DINAMICA PARCIAL 2'!$A$5:$T$772,13,FALSE) -> 0 | Y4: =VLOOKUP($A4,'TABLA DINAMICA PARCIAL 2'!$A$5:$T$772,14,FALSE) -> 0 | Z4: =VLOOKUP($A4,'TABLA DINAMICA PARCIAL 2'!$A$5:$T$772,15,FALSE) -> 0 | AA4: =VLOOKUP($A4,'TABLA DINAMICA PARCIAL 2'!$A$5:$T$772,16,FALSE) -> 0 | AB4: =VLOOKUP(I4,'TABLA DINAMICA PARCIAL 2'!I45:AB816,17,FALSE) -> 0 | AC4: =VLOOKUP(I4,'TABLA DINAMICA PARCIAL 2'!I45:AB816,18,FALSE) -> 0 | AD4: =VLOOKUP(I4,'TABLA DINAMICA PARCIAL 2'!I45:AB816,19,FALSE) -> 0 | AE4: =SUM(M4:AD4) -> 0 | AF4: =VLOOKUP($A4,'TABLA DINAMICA PARCIAL 3'!$A$5:$I$768,2,FALSE) -> 0 | AG4: =VLOOKUP($A4,'TABLA DINAMICA PARCIAL 3'!$A$5:$I$768,3,FALSE) -> 0 | AH4: =VLOOKUP($A4,'TABLA DINAMICA PARCIAL 3'!$A$5:$I$768,4,FALSE) -> 10 | AI4: =VLOOKUP($A4,'TABLA DINAMICA PARCIAL 3'!$A$5:$I$768,5,FALSE) -> 0 | AJ4: =VLOOKUP($A4,'TABLA DINAMICA PARCIAL 3'!$A$5:$I$768,6,FALSE) -> 0 | AK4: =VLOOKUP($A4,'TABLA DINAMICA PARCIAL 3'!$A$5:$I$768,7,FALSE) -> 0 | AL4: =VLOOKUP($A4,'TABLA DINAMICA PARCIAL 3'!$A$5:$I$768,8,FALSE) -> 0 | AM4: =SUM(AF4:AL4) -> 10 | AN4: =VLOOKUP($A4,'TABLA DINAMICA PARCIAL 4'!$A$5:$F$760,2,FALSE) -> 0 | AO4: =VLOOKUP($A4,'TABLA DINAMICA PARCIAL 4'!$A$5:$F$760,3,FALSE) -> 10 | AP4: =VLOOKUP($A4,'TABLA DINAMICA PARCIAL 4'!$A$5:$F$760,4,FALSE) -> 0 | AQ4: =VLOOKUP($A4,'TABLA DINAMICA PARCIAL 4'!$A$5:$F$760,5,FALSE) -> 0 | AR4: =VLOOKUP($A4,'TABLA DINAMICA PARCIAL 4'!$A$5:$F$760,6,FALSE) -> 0 | AS4: =SUM(AN4:AR4) -> 10 | AT4: =VLOOKUP($A4,'USUARIOS Y GRUPO'!$A$2:$D$851,4,FALSE) -> P19-MAT1022-10
A5: 159224 | B5: Miranda Sangabriel | C5: Agustin | D5: =VLOOKUP($A5,'TABLA DINAM PARCIAL 1'!$A$5:$I$793,2,FALSE) -> 0 | E5: =VLOOKUP($A5,'TABLA DINAM PARCIAL 1'!$A$5:$I$793,3,FALSE) -> 0 | F5: =VLOOKUP($A5,'TABLA DINAM PARCIAL 1'!$A$5:$I$793,4,FALSE) -> 0 | G5: =VLOOKUP($A5,'TABLA DINAM PARCIAL 1'!$A$5:$I$793,5,FALSE) -> 0 | H5: =VLOOKUP($A5,'TABLA DINAM PARCIAL 1'!$A$5:$I$793,6,FALSE) -> 0 | I5: =VLOOKUP($A5,'TABLA DINAM PARCIAL 1'!$A$5:$I$793,7,FALSE) -> 0 | J5: =VLOOKUP($A5,'TABLA DINAM PARCIAL 1'!$A$5:$I$793,8,FALSE) -> 10 | K5: =VLOOKUP($A5,'TABLA DINAM PARCIAL 1'!$A$5:$I$793,9,FALSE) -> 0 | L5: =SUM(D5:K5) -> 10 | M5: =VLOOKUP($A5,'TABLA DINAMICA PARCIAL 2'!$A$5:$T$772,2,FALSE) -> 0 | N5: =VLOOKUP($A5,'TABLA DINAMICA PARCIAL 2'!$A$5:$T$772,3,FALSE) -> 0 | O5: =VLOOKUP($A5,'TABLA DINAMICA PARCIAL 2'!$A$5:$T$772,4,FALSE) -> 0 | P5: =VLOOKUP($A5,'TABLA DINAMICA PARCIAL 2'!$A$5:$T$772,5,FALSE) -> 0 | Q5: =VLOOKUP($A5,'TABLA DINAMICA PARCIAL 2'!$A$5:$T$772,6,FALSE) -> 0 | R5: =VLOOKUP($A5,'TABLA DINAMICA PARCIAL 2'!$A$5:$T$772,7,FALSE) -> 0 | S5: =VLOOKUP($A5,'TABLA DINAMICA PARCIAL 2'!$A$5:$T$772,8,FALSE) -> 10 | T5: =VLOOKUP($A5,'TABLA DINAMICA PARCIAL 2'!$A$5:$T$772,9,FALSE) -> 0 | U5: =VLOOKUP($A5,'TABLA DINAMICA PARCIAL 2'!$A$5:$T$772,10,FALSE) -> 0 | V5: =VLOOKUP($A5,'TABLA DINAMICA PARCIAL 2'!$A$5:$T$772,11,FALSE) -> 0 | W5: =VLOOKUP($A5,'TABLA DINAMICA PARCIAL 2'!$A$5:$T$772,12,FALSE) -> 0 | X5: =VLOOKUP($A5,'TABLA DINAMICA PARCIAL 2'!$A$5:$T$772,13,FALSE) -> 0 | Y5: =VLOOKUP($A5,'TABLA DINAMICA PARCIAL 2'!$A$5:$T$772,14,FALSE) -> 0 | Z5: =VLOOKUP($A5,'TABLA DINAMICA PARCIAL 2'!$A$5:$T$772,15,FALSE) -> 0 | AA5: =VLOOKUP($A5,'TABLA DINAMICA PARCIAL 2'!$A$5:$T$772,16,FALSE) -> 0 | AB5: =VLOOKUP(I5,'TABLA DINAMICA PARCIAL 2'!I48:AB819,17,FALSE) -> 0 | AC5: =VLOOKUP(I5,'TABLA DINAMICA PARCIAL 2'!I48:AB819,18,FALSE) -> 0 | AD5: =VLOOKUP(I5,'TABLA DINAMICA PARCIAL 2'!I48:AB819,19,FALSE) -> 0 | AE5: =SUM(M5:AD5) -> 10 | AF5: =VLOOKUP($A5,'TABLA DINAMICA PARCIAL 3'!$A$5:$I$768,2,FALSE) -> 10 | AG5: =VLOOKUP($A5,'TABLA DINAMICA PARCIAL 3'!$A$5:$I$768,3,FALSE) -> 0 | AH5: =VLOOKUP($A5,'TABLA DINAMICA PARCIAL 3'!$A$5:$I$768,4,FALSE) -> 0 | AI5: =VLOOKUP($A5,'TABLA DINAMICA PARCIAL 3'!$A$5:$I$768,5,FALSE) -> 0 | AJ5: =VLOOKUP($A5,'TABLA DINAMICA PARCIAL 3'!$A$5:$I$768,6,FALSE) -> 0 | AK5: =VLOOKUP($A5,'TABLA DINAMICA PARCIAL 3'!$A$5:$I$768,7,FALSE) -> 0 | AL5: =VLOOKUP($A5,'TABLA DINAMICA PARCIAL 3'!$A$5:$I$768,8,FALSE) -> 10 | AM5: =SUM(AF5:AL5) -> 20 | AN5: =VLOOKUP($A5,'TABLA DINAMICA PARCIAL 4'!$A$5:$F$760,2,FALSE) -> 0 | AO5: =VLOOKUP($A5,'TABLA DINAMICA PARCIAL 4'!$A$5:$F$760,3,FALSE) -> 0 | AP5: =VLOOKUP($A5,'TABLA DINAMICA PARCIAL 4'!$A$5:$F$760,4,FALSE) -> 0 | AQ5: =VLOOKUP($A5,'TABLA DINAMICA PARCIAL 4'!$A$5:$F$760,5,FALSE) -> 0 | AR5: =VLOOKUP($A5,'TABLA DINAMICA PARCIAL 4'!$A$5:$F$760,6,FALSE) -> 0 | AS5: =SUM(AN5:AR5) -> 0 | AT5: =VLOOKUP($A5,'USUARIOS Y GRUPO'!$A$2:$D$851,4,FALSE) -> P19-MAT1022-10
A6: 162975 | B6: Rodríguez Conde | C6: Francisco Alejandro | D6: =VLOOKUP($A6,'TABLA DINAM PARCIAL 1'!$A$5:$I$793,2,FALSE) -> 0 | E6: =VLOOKUP(A6,'TABLA DINAM PARCIAL 1'!A340:I1128,3,FALSE) -> 0 | F6: =VLOOKUP(A6,'TABLA DINAM PARCIAL 1'!A340:I1128,4,FALSE) -> 0 | G6: =VLOOKUP(A6,'TABLA DINAM PARCIAL 1'!A340:I1128,5,FALSE) -> 0 | H6: =VLOOKUP(A6,'TABLA DINAM PARCIAL 1'!A340:I1128,6,FALSE) -> 0 | I6: =VLOOKUP(A6,'TABLA DINAM PARCIAL 1'!A340:I1128,7,FALSE) -> 0 | J6: =VLOOKUP(A6,'TABLA DINAM PARCIAL 1'!A340:I1128,8,FALSE) -> 10 | K6: =VLOOKUP(A6,'TABLA DINAM PARCIAL 1'!A340:I1128,9,FALSE) -> 0 | L6: =SUM(D6:K6) -> 10 | M6: =VLOOKUP($A6,'TABLA DINAMICA PARCIAL 2'!$A$5:$T$772,2,FALSE) -> 0 | N6: =VLOOKUP($A6,'TABLA DINAMICA PARCIAL 2'!$A$5:$T$772,3,FALSE) -> 10 | O6: =VLOOKUP($A6,'TABLA DINAMICA PARCIAL 2'!$A$5:$T$772,4,FALSE) -> 0 | P6: =VLOOKUP($A6,'TABLA DINAMICA PARCIAL 2'!$A$5:$T$772,5,FALSE) -> 0 | Q6: =VLOOKUP($A6,'TABLA DINAMICA PARCIAL 2'!$A$5:$T$772,6,FALSE) -> 0 | R6: =VLOOKUP($A6,'TABLA DINAMICA PARCIAL 2'!$A$5:$T$772,7,FALSE) -> 0 | S6: =VLOOKUP($A6,'TABLA DINAMICA PARCIAL 2'!$A$5:$T$772,8,FALSE) -> 0 | T6: =VLOOKUP($A6,'TABLA DINAMICA PARCIAL 2'!$A$5:$T$772,9,FALSE) -> 10 | U6: =VLOOKUP($A6,'TABLA DINAMICA PARCIAL 2'!$A$5:$T$772,10,FALSE) -> 0 | V6: =VLOOKUP($A6,'TABLA DINAMICA PARCIAL 2'!$A$5:$T$772,11,FALSE) -> 0 | W6: =VLOOKUP($A6,'TABLA DINAMICA PARCIAL 2'!$A$5:$T$772,12,FALSE) -> 0 | X6: =VLOOKUP($A6,'TABLA DINAMICA PARCIAL 2'!$A$5:$T$772,13,FALSE) -> 0 | Y6: =VLOOKUP($A6,'TABLA DINAMICA PARCIAL 2'!$A$5:$T$772,14,FALSE) -> 0 | Z6: =VLOOKUP($A6,'TABLA DINAMICA PARCIAL 2'!$A$5:$T$772,15,FALSE) -> 10 | AA6: =VLOOKUP($A6,'TABLA DINAMICA PARCIAL 2'!$A$5:$T$772,16,FALSE) -> 0 | AB6: =VLOOKUP(I6,'TABLA DINAMICA PARCIAL 2'!I377:AB1148,17,FALSE) -> 0 | AC6: =VLOOKUP(I6,'TABLA DINAMICA PARCIAL 2'!I377:AB1148,18,FALSE) -> 0 | AD6: =VLOOKUP(I6,'TABLA DINAMICA PARCIAL 2'!I377:AB1148,19,FALSE) -> 0 | AE6: =SUM(M6:AD6) -> 30 | AF6: =VLOOKUP($A6,'TABLA DINAMICA PARCIAL 3'!$A$5:$I$768,2,FALSE) -> 10 | AG6: =VLOOKUP($A6,'TABLA DINAMICA PARCIAL 3'!$A$5:$I$768,3,FALSE) -> 0 | AH6: =VLOOKUP($A6,'TABLA DINAMICA PARCIAL 3'!$A$5:$I$768,4,FALSE) -> 10 | AI6: =VLOOKUP($A6,'TABLA DINAMICA PARCIAL 3'!$A$5:$I$768,5,FALSE) -> 0 | AJ6: =VLOOKUP($A6,'TABLA DINAMICA PARCIAL 3'!$A$5:$I$768,6,FALSE) -> 0 | AK6: =VLOOKUP($A6,'TABLA DINAMICA PARCIAL 3'!$A$5:$I$768,7,FALSE) -> 10 | AL6: =VLOOKUP($A6,'TABLA DINAMICA PARCIAL 3'!$A$5:$I$768,8,FALSE) -> 0 | AM6: =SUM(AF6:AL6) -> 30 | AN6: =VLOOKUP($A6,'TABLA DINAMICA PARCIAL 4'!$A$5:$F$760,2,FALSE) -> 0 | AO6: =VLOOKUP($A6,'TABLA DINAMICA PARCIAL 4'!$A$5:$F$760,3,FALSE) -> 0 | AP6: =VLOOKUP($A6,'TABLA DINAMICA PARCIAL 4'!$A$5:$F$760,4,FALSE) -> 0 | AQ6: =VLOOKUP($A6,'TABLA DINAMICA PARCIAL 4'!$A$5:$F$760,5,FALSE) -> 10 | AR6: =VLOOKUP($A6,'TABLA DINAMICA PARCIAL 4'!$A$5:$F$760,6,FALSE) -> 0 | AS6: =SUM(AN6:AR6) -> 10 | AT6: =VLOOKUP($A6,'USUARIOS Y GRUPO'!$A$2:$D$851,4,FALSE) -> P19-MAT1022-10
A7: 164378 | B7: Guzman | C7: Moises | D7: =VLOOKUP($A7,'TABLA DINAM PARCIAL 1'!$A$5:$I$793,2,FALSE) -> 0 | E7: =VLOOKUP(A7,'TABLA DINAM PARCIAL 1'!A698:I1486,3,FALSE) -> 0 | F7: =VLOOKUP(A7,'TABLA DINAM PARCIAL 1'!A698:I1486,4,FALSE) -> 0 | G7: =VLOOKUP(A7,'TABLA DINAM PARCIAL 1'!A698:I1486,5,FALSE) -> 0 | H7: =VLOOKUP(A7,'TABLA DINAM PARCIAL 1'!A698:I1486,6,FALSE) -> 10 | I7: =VLOOKUP(A7,'TABLA DINAM PARCIAL 1'!A698:I1486,7,FALSE) -> 0 | J7: =VLOOKUP(A7,'TABLA DINAM PARCIAL 1'!A698:I1486,8,FALSE) -> 0 | K7: =VLOOKUP(A7,'TABLA DINAM PARCIAL 1'!A698:I1486,9,FALSE) -> 0 | L7: =SUM(D7:K7) -> 10 | M7: =VLOOKUP($A7,'TABLA DINAMICA PARCIAL 2'!$A$5:$T$772,2,FALSE) -> 0 | N7: =VLOOKUP($A7,'TABLA DINAMICA PARCIAL 2'!$A$5:$T$772,3,FALSE) -> 0 | O7: =VLOOKUP($A7,'TABLA DINAMICA PARCIAL 2'!$A$5:$T$772,4,FALSE) -> 0 | P7: =VLOOKUP($A7,'TABLA DINAMICA PARCIAL 2'!$A$5:$T$772,5,FALSE) -> 0 | Q7: =VLOOKUP($A7,'TABLA DINAMICA PARCIAL 2'!$A$5:$T$772,6,FALSE) -> 0 | R7: =VLOOKUP($A7,'TABLA DINAMICA PARCIAL 2'!$A$5:$T$772,7,FALSE) -> 0 | S7: =VLOOKUP($A7,'TABLA DINAMICA PARCIAL 2'!$A$5:$T$772,8,FALSE) -> 0 | T7: =VLOOKUP($A7,'TABLA DINAMICA PARCIAL 2'!$A$5:$T$772,9,FALSE) -> 10 | U7: =VLOOKUP($A7,'TABLA DINAMICA PARCIAL 2'!$A$5:$T$772,10,FALSE) -> 0 | V7: =VLOOKUP($A7,'TABLA DINAMICA PARCIAL 2'!$A$5:$T$772,11,FALSE) -> 0 | W7: =VLOOKUP($A7,'TABLA DINAMICA PARCIAL 2'!$A$5:$T$772,12,FALSE) -> 0 | X7: =VLOOKUP($A7,'TABLA DINAMICA PARCIAL 2'!$A$5:$T$772,13,FALSE) -> 0 | Y7: =VLOOKUP($A7,'TABLA DINAMICA PARCIAL 2'!$A$5:$T$772,14,FALSE) -> 0 | Z7: =VLOOKUP($A7,'TABLA DINAMICA PARCIAL 2'!$A$5:$T$772,15,FALSE) -> 0 | AA7: =VLOOKUP($A7,'TABLA DINAMICA PARCIAL 2'!$A$5:$T$772,16,FALSE) -> 0 | AB7: =VLOOKUP(I7,'TABLA DINAMICA PARCIAL 2'!I751:AB1522,17,FALSE) -> 0 | AC7: =VLOOKUP(I7,'TABLA DINAMICA PARCIAL 2'!I751:AB1522,18,FALSE) -> 0 | AD7: =VLOOKUP(I7,'TABLA DINAMICA PARCIAL 2'!I751:AB1522,19,FALSE) -> 0 | AE7: =SUM(M7:AD7) -> 10 | AF7: =VLOOKUP($A7,'TABLA DINAMICA PARCIAL 3'!$A$5:$I$768,2,FALSE) -> 10 | AG7: =VLOOKUP($A7,'TABLA DINAMICA PARCIAL 3'!$A$5:$I$768,3,FALSE) -> 0 | AH7: =VLOOKUP($A7,'TABLA DINAMICA PARCIAL 3'!$A$5:$I$768,4,FALSE) -> 10 | AI7: =VLOOKUP($A7,'TABLA DINAMICA PARCIAL 3'!$A$5:$I$768,5,FALSE) -> 0 | AJ7: =VLOOKUP($A7,'TABLA DINAMICA PARCIAL 3'!$A$5:$I$768,6,FALSE) -> 0 | AK7: =VLOOKUP($A7,'TABLA DINAMICA PARCIAL 3'!$A$5:$I$768,7,FALSE) -> 0 | AL7: =VLOOKUP($A7,'TABLA DINAMICA PARCIAL 3'!$A$5:$I$768,8,FALSE) -> 10 | AM7: =SUM(AF7:AL7) -> 30 | AN7: =VLOOKUP($A7,'TABLA DINAMICA PARCIAL 4'!$A$5:$F$760,2,FALSE) -> 0 | AO7: =VLOOKUP($A7,'TABLA DINAMICA PARCIAL 4'!$A$5:$F$760,3,FALSE) -> 10 | AP7: =VLOOKUP($A7,'TABLA DINAMICA PARCIAL 4'!$A$5:$F$760,4,FALSE) -> 0 | AQ7: =VLOOKUP($A7,'TABLA DINAMICA PARCIAL 4'!$A$5:$F$760,5,FALSE) -> 0 | AR7: =VLOOKUP($A7,'TABLA DINAMICA PARCIAL 4'!$A$5:$F$760,6,FALSE) -> 0 | AS7: =SUM(AN7:AR7) -> 10 | AT7: =VLOOKUP($A7,'USUARIOS Y GRUPO'!$A$2:$D$851,4,FALSE) -> P19-MAT1022-10
A8: 164890 | B8: López Mejia | C8: Karla Yaret | D8: =VLOOKUP($A8,'TABLA DINAM PARCIAL 1'!$A$5:$I$793,2,FALSE) -> 0 | E8: =VLOOKUP(A8,'TABLA DINAM PARCIAL 1'!A783:I1571,3,FALSE) -> 0 | F8: =VLOOKUP(A8,'TABLA DINAM PARCIAL 1'!A783:I1571,4,FALSE) -> 0 | G8: =VLOOKUP(A8,'TABLA DINAM PARCIAL 1'!A783:I1571,5,FALSE) -> 10 | H8: =VLOOKUP(A8,'TABLA DINAM PARCIAL 1'!A783:I1571,6,FALSE) -> 0 | I8: =VLOOKUP(A8,'TABLA DINAM PARCIAL 1'!A783:I1571,7,FALSE) -> 0 | J8: =VLOOKUP(A8,'TABLA DINAM PARCIAL 1'!A783:I1571,8,FALSE) -> 0 | K8: =VLOOKUP(A8,'TABLA DINAM PARCIAL 1'!A783:I1571,9,FALSE) -> 0 | L8: =SUM(D8:K8) -> 10 | M8: =VLOOKUP($A8,'TABLA DINAMICA PARCIAL 2'!$A$5:$T$772,2,FALSE) -> 0 | N8: =VLOOKUP($A8,'TABLA DINAMICA PARCIAL 2'!$A$5:$T$772,3,FALSE) -> 0 | O8: =VLOOKUP($A8,'TABLA DINAMICA PARCIAL 2'!$A$5:$T$772,4,FALSE) -> 0 | P8: =VLOOKUP($A8,'TABLA DINAMICA PARCIAL 2'!$A$5:$T$772,5,FALSE) -> 10 | Q8: =VLOOKUP($A8,'TABLA DINAMICA PARCIAL 2'!$A$5:$T$772,6,FALSE) -> 0 | R8: =VLOOKUP($A8,'TABLA DINAMICA PARCIAL 2'!$A$5:$T$772,7,FALSE) -> 0 | S8: =VLOOKUP($A8,'TABLA DINAMICA PARCIAL 2'!$A$5:$T$772,8,FALSE) -> 10 | T8: =VLOOKUP($A8,'TABLA DINAMICA PARCIAL 2'!$A$5:$T$772,9,FALSE) -> 0 | U8: =VLOOKUP($A8,'TABLA DINAMICA PARCIAL 2'!$A$5:$T$772,10,FALSE) -> 0 | V8: =VLOOKUP($A8,'TABLA DINAMICA PARCIAL 2'!$A$5:$T$772,11,FALSE) -> 0 | W8: =VLOOKUP($A8,'TABLA DINAMICA PARCIAL 2'!$A$5:$T$772,12,FALSE) -> 0 | X8: =VLOOKUP($A8,'TABLA DINAMICA PARCIAL 2'!$A$5:$T$772,13,FALSE) -> 0 | Y8: =VLOOKUP($A8,'TABLA DINAMICA PARCIAL 2'!$A$5:$T$772,14,FALSE) -> 0 | Z8: =VLOOKUP($A8,'TABLA DINAMICA PARCIAL 2'!$A$5:$T$772,15,FALSE) -> 0 | AA8: =VLOOKUP($A8,'TABLA DINAMICA PARCIAL 2'!$A$5:$T$772,16,FALSE) -> 0 | AB8: =VLOOKUP(I8,'TABLA DINAMICA PARCIAL 2'!I845:AB1616,17,FALSE) -> #N/A | AC8: =VLOOKUP(I8,'TABLA DINAMICA PARCIAL 2'!I845:AB1616,18,FALSE) -> #N/A | AD8: =VLOOKUP(I8,'TABLA DINAMICA PARCIAL 2'!I845:AB1616,19,FALSE) -> #N/A | AE8: =SUM(M8:AD8) -> #N/A | AF8: =VLOOKUP($A8,'TABLA DINAMICA PARCIAL 3'!$A$5:$I$768,2,FALSE) -> 0 | AG8: =VLOOKUP($A8,'TABLA DINAMICA PARCIAL 3'!$A$5:$I$768,3,FALSE) -> 0 | AH8: =VLOOKUP($A8,'TABLA DINAMICA PARCIAL 3'!$A$5:$I$768,4,FALSE) -> 0 | AI8: =VLOOKUP($A8,'TABLA DINAMICA PARCIAL 3'!$A$5:$I$768,5,FALSE) -> 0 | AJ8: =VLOOKUP($A8,'TABLA DINAMICA PARCIAL 3'!$A$5:$I$768,6,FALSE) -> 0 | AK8: =VLOOKUP($A8,'TABLA DINAMICA PARCIAL 3'!$A$5:$I$768,7,FALSE) -> 0 | AL8: =VLOOKUP($A8,'TABLA DINAMICA PARCIAL 3'!$A$5:$I$768,8,FALSE) -> 10 | AM8: =SUM(AF8:AL8) -> 10 | AN8: =VLOOKUP($A8,'TABLA DINAMICA PARCIAL 4'!$A$5:$F$760,2,FALSE) -> 10 | AO8: =VLOOKUP($A8,'TABLA DINAMICA PARCIAL 4'!$A$5:$F$760,3,FALSE) -> 0 | AP8: =VLOOKUP($A8,'TABLA DINAMICA PARCIAL 4'!$A$5:$F$760,4,FALSE) -> 0 | AQ8: =VLOOKUP($A8,'TABLA DINAMICA PARCIAL 4'!$A$5:$F$760,5,FALSE) -> 10 | AR8: =VLOOKUP($A8,'TABLA DINAMICA PARCIAL 4'!$A$5:$F$760,6,FALSE) -> 0 | AS8: =SUM(AN8:AR8) -> 20 | AT8: =VLOOKUP($A8,'USUARIOS Y GRUPO'!$A$2:$D$851,4,FALSE) -> P19-MAT1022-10
A9: 161044 | B9: Thompson Pérez | C9: Malcolm | D9: =VLOOKUP($A9,'TABLA DINAM PARCIAL 1'!$A$5:$I$793,2,FALSE) -> 10 | E9: =VLOOKUP(A9,'TABLA DINAM PARCIAL 1'!A70:I858,3,FALSE) -> 0 | F9: =VLOOKUP(A9,'TABLA DINAM PARCIAL 1'!A70:I858,4,FALSE) -> 0 | G9: =VLOOKUP(A9,'TABLA DINAM PARCIAL 1'!A70:I858,5,FALSE) -> 0 | H9: =VLOOKUP(A9,'TABLA DINAM PARCIAL 1'!A70:I858,6,FALSE) -> 0 | I9: =VLOOKUP(A9,'TABLA DINAM PARCIAL 1'!A70:I858,7,FALSE) -> 0 | J9: =VLOOKUP(A9,'TABLA DINAM PARCIAL 1'!A70:I858,8,FALSE) -> 10 | K9: =VLOOKUP(A9,'TABLA DINAM PARCIAL 1'!A70:I858,9,FALSE) -> 0 | L9: =SUM(D9:K9) -> 20 | M9: =VLOOKUP($A9,'TABLA DINAMICA PARCIAL 2'!$A$5:$T$772,2,FALSE) -> 0 | N9: =VLOOKUP($A9,'TABLA DINAMICA PARCIAL 2'!$A$5:$T$772,3,FALSE) -> 0 | O9: =VLOOKUP($A9,'TABLA DINAMICA PARCIAL 2'!$A$5:$T$772,4,FALSE) -> 0 | P9: =VLOOKUP($A9,'TABLA DINAMICA PARCIAL 2'!$A$5:$T$772,5,FALSE) -> 0 | Q9: =VLOOKUP($A9,'TABLA DINAMICA PARCIAL 2'!$A$5:$T$772,6,FALSE) -> 0 | R9: =VLOOKUP($A9,'TABLA DINAMICA PARCIAL 2'!$A$5:$T$772,7,FALSE) -> 0 | S9: =VLOOKUP($A9,'TABLA DINAMICA PARCIAL 2'!$A$5:$T$772,8,FALSE) -> 0 | T9: =VLOOKUP($A9,'TABLA DINAMICA PARCIAL 2'!$A$5:$T$772,9,FALSE) -> 0 | U9: =VLOOKUP($A9,'TABLA DINAMICA PARCIAL 2'!$A$5:$T$772,10,FALSE) -> 0 | V9: =VLOOKUP($A9,'TABLA DINAMICA PARCIAL 2'!$A$5:$T$772,11,FALSE) -> 0 | W9: =VLOOKUP($A9,'TABLA DINAMICA PARCIAL 2'!$A$5:$T$772,12,FALSE) -> 0 | X9: =VLOOKUP($A9,'TABLA DINAMICA PARCIAL 2'!$A$5:$T$772,13,FALSE) -> 0 | Y9: =VLOOKUP($A9,'TABLA DINAMICA PARCIAL 2'!$A$5:$T$772,14,FALSE) -> 0 | Z9: =VLOOKUP($A9,'TABLA DINAMICA PARCIAL 2'!$A$5:$T$772,15,FALSE) -> 10 | AA9: =VLOOKUP($A9,'TABLA DINAMICA PARCIAL 2'!$A$5:$T$772,16,FALSE) -> 0 | AB9: =VLOOKUP(I9,'TABLA DINAMICA PARCIAL 2'!I91:AB862,17,FALSE) -> 0 | AC9: =VLOOKUP(I9,'TABLA DINAMICA PARCIAL 2'!I91:AB862,18,FALSE) -> 0 | AD9: =VLOOKUP(I9,'TABLA DINAMICA PARCIAL 2'!I91:AB862,19,FALSE) -> 0 | AE9: =SUM(M9:AD9) -> 10 | AF9: =VLOOKUP($A9,'TABLA DINAMICA PARCIAL 3'!$A$5:$I$768,2,FALSE) -> 0 | AG9: =VLOOKUP($A9,'TABLA DINAMICA PARCIAL 3'!$A$5:$I$768,3,FALSE) -> 0 | AH9: =VLOOKUP($A9,'TABLA DINAMICA PARCIAL 3'!$A$5:$I$768,4,FALSE) -> 10 | AI9: =VLOOKUP($A9,'TABLA DINAMICA PARCIAL 3'!$A$5:$I$768,5,FALSE) -> 0 | AJ9: =VLOOKUP($A9,'TABLA DINAMICA PARCIAL 3'!$A$5:$I$768,6,FALSE) -> 10 | AK9: =VLOOKUP($A9,'TABLA DINAMICA PARCIAL 3'!$A$5:$I$768,7,FALSE) -> 0 | AL9: =VLOOKUP($A9,'TABLA DINAMICA PARCIAL 3'!$A$5:$I$768,8,FALSE) -> 0 | AM9: =SUM(AF9:AL9) -> 20 | AN9: =VLOOKUP($A9,'TABLA DINAMICA PARCIAL 4'!$A$5:$F$760,2,FALSE) -> 0 | AO9: =VLOOKUP($A9,'TABLA DINAMICA PARCIAL 4'!$A$5:$F$760,3,FALSE) -> 0 | AP9: =VLOOKUP($A9,'TABLA DINAMICA PARCIAL 4'!$A$5:$F$760,4,FALSE) -> 0 | AQ9: =VLOOKUP($A9,'TABLA DINAMICA PARCIAL 4'!$A$5:$F$760,5,FALSE) -> 0 | AR9: =VLOOKUP($A9,'TABLA DINAMICA PARCIAL 4'!$A$5:$F$760,6,FALSE) -> 0 | AS9: =SUM(AN9:AR9) -> 0 | AT9: =VLOOKUP($A9,'USUARIOS Y GRUPO'!$A$2:$D$851,4,FALSE) -> P19-MAT1022-10
A10: 162447 | B10: Guirado Acosta | C10: David Israel | D10: =VLOOKUP($A10,'TABLA DINAM PARCIAL 1'!$A$5:$I$793,2,FALSE) -> 10 | E10: =VLOOKUP(A10,'TABLA DINAM PARCIAL 1'!A206:I994,3,FALSE) -> 0 | F10: =VLOOKUP(A10,'TABLA DINAM PARCIAL 1'!A206:I994,4,FALSE) -> 0 | G10: =VLOOKUP(A10,'TABLA DINAM PARCIAL 1'!A206:I994,5,FALSE) -> 0 | H10: =VLOOKUP(A10,'TABLA DINAM PARCIAL 1'!A206:I994,6,FALSE) -> 0 | I10: =VLOOKUP(A10,'TABLA DINAM PARCIAL 1'!A206:I994,7,FALSE) -> 0 | J10: =VLOOKUP(A10,'TABLA DINAM PARCIAL 1'!A206:I994,8,FALSE) -> 10 | K10: =VLOOKUP(A10,'TABLA DINAM PARCIAL 1'!A206:I994,9,FALSE) -> 0 | L10: =SUM(D10:K10) -> 20 | M10: =VLOOKUP($A10,'TABLA DINAMICA PARCIAL 2'!$A$5:$T$772,2,FALSE) -> 0 | N10: =VLOOKUP($A10,'TABLA DINAMICA PARCIAL 2'!$A$5:$T$772,3,FALSE) -> 0 | O10: =VLOOKUP($A10,'TABLA DINAMICA PARCIAL 2'!$A$5:$T$772,4,FALSE) -> 0 | P10: =VLOOKUP($A10,'TABLA DINAMICA PARCIAL 2'!$A$5:$T$772,5,FALSE) -> 0 | Q10: =VLOOKUP($A10,'TABLA DINAMICA PARCIAL 2'!$A$5:$T$772,6,FALSE) -> 0 | R10: =VLOOKUP($A10,'TABLA DINAMICA PARCIAL 2'!$A$5:$T$772,7,FALSE) -> 0 | S10: =VLOOKUP($A10,'TABLA DINAMICA PARCIAL 2'!$A$5:$T$772,8,FALSE) -> 0 | T10: =VLOOKUP($A10,'TABLA DINAMICA PARCIAL 2'!$A$5:$T$772,9,FALSE) -> 0 | U10: =VLOOKUP($A10,'TABLA DINAMICA PARCIAL 2'!$A$5:$T$772,10,FALSE) -> 0 | V10: =VLOOKUP($A10,'TABLA DINAMICA PARCIAL 2'!$A$5:$T$772,11,FALSE) -> 0 | W10: =VLOOKUP($A10,'TABLA DINAMICA PARCIAL 2'!$A$5:$T$772,12,FALSE) -> 0 | X10: =VLOOKUP($A10,'TABLA DINAMICA PARCIAL 2'!$A$5:$T$772,13,FALSE) -> 0 | Y10: =VLOOKUP($A10,'TABLA DINAMICA PARCIAL 2'!$A$5:$T$772,14,FALSE) -> 0 | Z10: =VLOOKUP($A10,'TABLA DINAMICA PARCIAL 2'!$A$5:$T$772,15,FALSE) -> 10 | AA10: =VLOOKUP($A10,'TABLA DINAMICA PARCIAL 2'!$A$5:$T$772,16,FALSE) -> 0 | AB10: =VLOOKUP(I10,'TABLA DINAMICA PARCIAL 2'!I236:AB1007,17,FALSE) -> 0 | AC10: =VLOOKUP(I10,'TABLA DINAMICA PARCIAL 2'!I236:AB1007,18,FALSE) -> 0 | AD10: =VLOOKUP(I10,'TABLA DINAMICA PARCIAL 2'!I236:AB1007,19,FALSE) -> 0 | AE10: =SUM(M10:AD10) -> 10 | AF10: =VLOOKUP($A10,'TABLA DINAMICA PARCIAL 3'!$A$5:$I$768,2,FALSE) -> 10 | AG10: =VLOOKUP($A10,'TABLA DINAMICA PARCIAL 3'!$A$5:$I$768,3,FALSE) -> 0 | AH10: =VLOOKUP($A10,'TABLA DINAMICA PARCIAL 3'!$A$5:$I$768,4,FALSE) -> 10 | AI10: =VLOOKUP($A10,'TABLA DINAMICA PARCIAL 3'!$A$5:$I$768,5,FALSE) -> 0 | AJ10: =VLOOKUP($A10,'TABLA DINAMICA PARCIAL 3'!$A$5:$I$768,6,FALSE) -> 10 | AK10: =VLOOKUP($A10,'TABLA DINAMICA PARCIAL 3'!$A$5:$I$768,7,FALSE) -> 10 | AL10: =VLOOKUP($A10,'TABLA DINAMICA PARCIAL 3'!$A$5:$I$768,8,FALSE) -> 0 | AM10: =SUM(AF10:AL10) -> 40 | AN10: =VLOOKUP($A10,'TABLA DINAMICA PARCIAL 4'!$A$5:$F$760,2,FALSE) -> 0 | AO10: =VLOOKUP($A10,'TABLA DINAMICA PARCIAL 4'!$A$5:$F$760,3,FALSE) -> 0 | AP10: =VLOOKUP($A10,'TABLA DINAMICA PARCIAL 4'!$A$5:$F$760,4,FALSE) -> 0 | AQ10: =VLOOKUP($A10,'TABLA DINAMICA PARCIAL 4'!$A$5:$F$760,5,FALSE) -> 10 | AR10: =VLOOKUP($A10,'TABLA DINAMICA PARCIAL 4'!$A$5:$F$760,6,FALSE) -> 0 | AS10: =SUM(AN10:AR10) -> 10 | AT10: =VLOOKUP($A10,'USUARIOS Y GRUPO'!$A$2:$D$851,4,FALSE) -> P19-MAT1022-10
A11: 162470 | B11: Escobar Moya | C11: Norma Silvia | D11: =VLOOKUP($A11,'TABLA DINAM PARCIAL 1'!$A$5:$I$793,2,FALSE) -> 10 | E11: =VLOOKUP(A11,'TABLA DINAM PARCIAL 1'!A214:I1002,3,FALSE) -> 0 | F11: =VLOOKUP(A11,'TABLA DINAM PARCIAL 1'!A214:I1002,4,FALSE) -> 0 | G11: =VLOOKUP(A11,'TABLA DINAM PARCIAL 1'!A214:I1002,5,FALSE) -> 0 | H11: =VLOOKUP(A11,'TABLA DINAM PARCIAL 1'!A214:I1002,6,FALSE) -> 10 | I11: =VLOOKUP(A11,'TABLA DINAM PARCIAL 1'!A214:I1002,7,FALSE) -> 0 | J11: =VLOOKUP(A11,'TABLA DINAM PARCIAL 1'!A214:I1002,8,FALSE) -> 0 | K11: =VLOOKUP(A11,'TABLA DINAM PARCIAL 1'!A214:I1002,9,FALSE) -> 0 | L11: =SUM(D11:K11) -> 20 | M11: =VLOOKUP($A11,'TABLA DINAMICA PARCIAL 2'!$A$5:$T$772,2,FALSE) -> 0 | N11: =VLOOKUP($A11,'TABLA DINAMICA PARCIAL 2'!$A$5:$T$772,3,FALSE) -> 0 | O11: =VLOOKUP($A11,'TABLA DINAMICA PARCIAL 2'!$A$5:$T$772,4,FALSE) -> 0 | P11: =VLOOKUP($A11,'TABLA DINAMICA PARCIAL 2'!$A$5:$T$772,5,FALSE) -> 0 | Q11: =VLOOKUP($A11,'TABLA DINAMICA PARCIAL 2'!$A$5:$T$772,6,FALSE) -> 0 | R11: =VLOOKUP($A11,'TABLA DINAMICA PARCIAL 2'!$A$5:$T$772,7,FALSE) -> 0 | S11: =VLOOKUP($A11,'TABLA DINAMICA PARCIAL 2'!$A$5:$T$772,8,FALSE) -> 0 | T11: =VLOOKUP($A11,'TABLA DINAMICA PARCIAL 2'!$A$5:$T$772,9,FALSE) -> 0 | U11: =VLOOKUP($A11,'TABLA DINAMICA PARCIAL 2'!$A$5:$T$772,10,FALSE) -> 10 | V11: =VLOOKUP($A11,'TABLA DINAMICA PARCIAL 2'!$A$5:$T$772,11,FALSE) -> 0 | W11: =VLOOKUP($A11,'TABLA DINAMICA PARCIAL 2'!$A$5:$T$772,12,FALSE) -> 0 | X11: =VLOOKUP($A11,'TABLA DINAMICA PARCIAL 2'!$A$5:$T$772,13,FALSE) -> 0 | Y11: =VLOOKUP($A11,'TABLA DINAMICA PARCIAL 2'!$A$5:$T$772,14,FALSE) -> 10 | Z11: =VLOOKUP($A11,'TABLA DINAMICA PARCIAL 2'!$A$5:$T$772,15,FALSE) -> 0 | AA11: =VLOOKUP($A11,'TABLA DINAMICA PARCIAL 2'!$A$5:$T$772,16,FALSE) -> 0 | AB11: =VLOOKUP(I11,'TABLA DINAMICA PARCIAL 2'!I244:AB1015,17,FALSE) -> 0 | AC11: =VLOOKUP(I11,'TABLA DINAMICA PARCIAL 2'!I244:AB1015,18,FALSE) -> 0 | AD11: =VLOOKUP(I11,'TABLA DINAMICA PARCIAL 2'!I244:AB1015,19,FALSE) -> 0 | AE11: =SUM(M11:AD11) -> 20 | AF11: =VLOOKUP($A11,'TABLA DINAMICA PARCIAL 3'!$A$5:$I$768,2,FALSE) -> 0 | AG11: =VLOOKUP($A11,'TABLA DINAMICA PARCIAL 3'!$A$5:$I$768,3,FALSE) -> 0 | AH11: =VLOOKUP($A11,'TABLA DINAMICA PARCIAL 3'!$A$5:$I$768,4,FALSE) -> 10 | AI11: =VLOOKUP($A11,'TABLA DINAMICA PARCIAL 3'!$A$5:$I$768,5,FALSE) -> 0 | AJ11: =VLOOKUP($A11,'TABLA DINAMICA PARCIAL 3'!$A$5:$I$768,6,FALSE) -> 0 | AK11: =VLOOKUP($A11,'TABLA DINAMICA PARCIAL 3'!$A$5:$I$768,7,FALSE) -> 0 | AL11: =VLOOKUP($A11,'TABLA DINAMICA PARCIAL 3'!$A$5:$I$768,8,FALSE) -> 0 | AM11: =SUM(AF11:AL11) -> 10 | AN11: =VLOOKUP($A11,'TABLA DINAMICA PARCIAL 4'!$A$5:$F$760,2,FALSE) -> 0 | AO11: =VLOOKUP($A11,'TABLA DINAMICA PARCIAL 4'!$A$5:$F$760,3,FALSE) -> 0 | AP11: =VLOOKUP($A11,'TABLA DINAMICA PARCIAL 4'!$A$5:$F$760,4,FALSE) -> 0 | AQ11: =VLOOKUP($A11,'TABLA DINAMICA PARCIAL 4'!$A$5:$F$760,5,FALSE) -> 0 | AR11: =VLOOKUP($A11,'TABLA DINAMICA PARCIAL 4'!$A$5:$F$760,6,FALSE) -> 0 | AS11: =SUM(AN11:AR11) -> 0 | AT11: =VLOOKUP($A11,'USUARIOS Y GRUPO'!$A$2:$D$851,4,FALSE) -> P19-MAT1022-10
A12: 163018 | B12: Sandoval Morales | C12: Aylin Michelle | D12: =VLOOKUP($A12,'TABLA DINAM PARCIAL 1'!$A$5:$I$793,2,FALSE) -> 0 | E12: =VLOOKUP(A12,'TABLA DINAM PARCIAL 1'!A350:I1138,3,FALSE) -> 0 | F12: =VLOOKUP(A12,'TABLA DINAM PARCIAL 1'!A350:I1138,4,FALSE) -> 0 | G12: =VLOOKUP(A12,'TABLA DINAM PARCIAL 1'!A350:I1138,5,FALSE) -> 0 | H12: =VLOOKUP(A12,'TABLA DINAM PARCIAL 1'!A350:I1138,6,FALSE) -> 10 | I12: =VLOOKUP(A12,'TABLA DINAM PARCIAL 1'!A350:I1138,7,FALSE) -> 0 | J12: =VLOOKUP(A12,'TABLA DINAM PARCIAL 1'!A350:I1138,8,FALSE) -> 10 | K12: =VLOOKUP(A12,'TABLA DINAM PARCIAL 1'!A350:I1138,9,FALSE) -> 0 | L12: =SUM(D12:K12) -> 20 | M12: =VLOOKUP($A12,'TABLA DINAMICA PARCIAL 2'!$A$5:$T$772,2,FALSE) -> 0 | N12: =VLOOKUP($A12,'TABLA DINAMICA PARCIAL 2'!$A$5:$T$772,3,FALSE) -> 0 | O12: =VLOOKUP($A12,'TABLA DINAMICA PARCIAL 2'!$A$5:$T$772,4,FALSE) -> 0 | P12: =VLOOKUP($A12,'TABLA DINAMICA PARCIAL 2'!$A$5:$T$772,5,FALSE) -> 0 | Q12: =VLOOKUP($A12,'TABLA DINAMICA PARCIAL 2'!$A$5:$T$772,6,FALSE) -> 0 | R12: =VLOOKUP($A12,'TABLA DINAMICA PARCIAL 2'!$A$5:$T$772,7,FALSE) -> 0 | S12: =VLOOKUP($A12,'TABLA DINAMICA PARCIAL 2'!$A$5:$T$772,8,FALSE) -> 0 | T12: =VLOOKUP($A12,'TABLA DINAMICA PARCIAL 2'!$A$5:$T$772,9,FALSE) -> 0 | U12: =VLOOKUP($A12,'TABLA DINAMICA PARCIAL 2'!$A$5:$T$772,10,FALSE) -> 0 | V12: =VLOOKUP($A12,'TABLA DINAMICA PARCIAL 2'!$A$5:$T$772,11,FALSE) -> 10 | W12: =VLOOKUP($A12,'TABLA DINAMICA PARCIAL 2'!$A$5:$T$772,12,FALSE) -> 0 | X12: =VLOOKUP($A12,'TABLA DINAMICA PARCIAL 2'!$A$5:$T$772,13,FALSE) -> 0 | Y12: =VLOOKUP($A12,'TABLA DINAMICA PARCIAL 2'!$A$5:$T$772,14,FALSE) -> 0 | Z12: =VLOOKUP($A12,'TABLA DINAMICA PARCIAL 2'!$A$5:$T$772,15,FALSE) -> 0 | AA12: =VLOOKUP($A12,'TABLA DINAMICA PARCIAL 2'!$A$5:$T$772,16,FALSE) -> 0 | AB12: =VLOOKUP(I12,'TABLA DINAMICA PARCIAL 2'!I387:AB1158,17,FALSE) -> 0 | AC12: =VLOOKUP(I12,'TABLA DINAMICA PARCIAL 2'!I387:AB1158,18,FALSE) -> 0 | AD12: =VLOOKUP(I12,'TABLA DINAMICA PARCIAL 2'!I387:AB1158,19,FALSE) -> 0 | AE12: =SUM(M12:AD12) -> 10 | AF12: =VLOOKUP($A12,'TABLA DINAMICA PARCIAL 3'!$A$5:$I$768,2,FALSE) -> 0 | AG12: =VLOOKUP($A12,'TABLA DINAMICA PARCIAL 3'!$A$5:$I$768,3,FALSE) -> 0 | AH12: =VLOOKUP($A12,'TABLA DINAMICA PARCIAL 3'!$A$5:$I$768,4,FALSE) -> 10 | AI12: =VLOOKUP($A12,'TABLA DINAMICA PARCIAL 3'!$A$5:$I$768,5,FALSE) -> 0 | AJ12: =VLOOKUP($A12,'TABLA DINAMICA PARCIAL 3'!$A$5:$I$768,6,FALSE) -> 10 | AK12: =VLOOKUP($A12,'TABLA DINAMICA PARCIAL 3'!$A$5:$I$768,7,FALSE) -> 10 | AL12: =VLOOKUP($A12,'TABLA DINAMICA PARCIAL 3'!$A$5:$I$768,8,FALSE) -> 0 | AM12: =SUM(AF12:AL12) -> 30 | AN12: =VLOOKUP($A12,'TABLA DINAMICA PARCIAL 4'!$A$5:$F$760,2,FALSE) -> 0 | AO12: =VLOOKUP($A12,'TABLA DINAMICA PARCIAL 4'!$A$5:$F$760,3,FALSE) -> 10 | AP12: =VLOOKUP($A12,'TABLA DINAMICA PARCIAL 4'!$A$5:$F$760,4,FALSE) -> 0 | AQ12: =VLOOKUP($A12,'TABLA DINAMICA PARCIAL 4'!$A$5:$F$760,5,FALSE) -> 10 | AR12: =VLOOKUP($A12,'TABLA DINAMICA PARCIAL 4'!$A$5:$F$760,6,FALSE) -> 0 | AS12: =SUM(AN12:AR12) -> 20 | AT12: =VLOOKUP($A12,'USUARIOS Y GRUPO'!$A$2:$D$851,4,FALSE) -> P19-MAT1022-10
A13: 163172 | B13: Marín Morales | C13: Angélica | D13: =VLOOKUP($A13,'TABLA DINAM PARCIAL 1'!$A$5:$I$793,2,FALSE) -> 10 | E13: =VLOOKUP(A13,'TABLA DINAM PARCIAL 1'!A388:I1176,3,FALSE) -> 0 | F13: =VLOOKUP(A13,'TABLA DINAM PARCIAL 1'!A388:I1176,4,FALSE) -> 0 | G13: =VLOOKUP(A13,'TABLA DINAM PARCIAL 1'!A388:I1176,5,FALSE) -> 0 | H13: =VLOOKUP(A13,'TABLA DINAM PARCIAL 1'!A388:I1176,6,FALSE) -> 0 | I13: =VLOOKUP(A13,'TABLA DINAM PARCIAL 1'!A388:I1176,7,FALSE) -> 10 | J13: =VLOOKUP(A13,'TABLA DINAM PARCIAL 1'!A388:I1176,8,FALSE) -> 0 | K13: =VLOOKUP(A13,'TABLA DINAM PARCIAL 1'!A388:I1176,9,FALSE) -> 0 | L13: =SUM(D13:K13) -> 20 | M13: =VLOOKUP($A13,'TABLA DINAMICA PARCIAL 2'!$A$5:$T$772,2,FALSE) -> 0 | N13: =VLOOKUP($A13,'TABLA DINAMICA PARCIAL 2'!$A$5:$T$772,3,FALSE) -> 0 | O13: =VLOOKUP($A13,'TABLA DINAMICA PARCIAL 2'!$A$5:$T$772,4,FALSE) -> 0 | P13: =VLOOKUP($A13,'TABLA DINAMICA PARCIAL 2'!$A$5:$T$772,5,FALSE) -> 0 | Q13: =VLOOKUP($A13,'TABLA DINAMICA PARCIAL 2'!$A$5:$T$772,6,FALSE) -> 0 | R13: =VLOOKUP($A13,'TABLA DINAMICA PARCIAL 2'!$A$5:$T$772,7,FALSE) -> 0 | S13: =VLOOKUP($A13,'TABLA DINAMICA PARCIAL 2'!$A$5:$T$772,8,FALSE) -> 0 | T13: =VLOOKUP($A13,'TABLA DINAMICA PARCIAL 2'!$A$5:$T$772,9,FALSE) -> 0 | U13: =VLOOKUP($A13,'TABLA DINAMICA PARCIAL 2'!$A$5:$T$772,10,FALSE) -> 10 | V13: =VLOOKUP($A13,'TABLA DINAMICA PARCIAL 2'!$A$5:$T$772,11,FALSE) -> 0 | W13: =VLOOKUP($A13,'TABLA DINAMICA PARCIAL 2'!$A$5:$T$772,12,FALSE) -> 0 | X13: =VLOOKUP($A13,'TABLA DINAMICA PARCIAL 2'!$A$5:$T$772,13,FALSE) -> 0 | Y13: =VLOOKUP($A13,'TABLA DINAMICA PARCIAL 2'!$A$5:$T$772,14,FALSE) -> 0 | Z13: =VLOOKUP($A13,'TABLA DINAMICA PARCIAL 2'!$A$5:$T$772,15,FALSE) -> 0 | AA13: =VLOOKUP($A13,'TABLA DINAMICA PARCIAL 2'!$A$5:$T$772,16,FALSE) -> 0 | AB13: =VLOOKUP(I13,'TABLA DINAMICA PARCIAL 2'!I425:AB1196,17,FALSE) -> 0 | AC13: =VLOOKUP(I13,'TABLA DINAMICA PARCIAL 2'!I425:AB1196,18,FALSE) -> 0 | AD13: =VLOOKUP(I13,'TABLA DINAMICA PARCIAL 2'!I425:AB1196,19,FALSE) -> 0 | AE13: =SUM(M13:AD13) -> 10 | AF13: =VLOOKUP($A13,'TABLA DINAMICA PARCIAL 3'!$A$5:$I$768,2,FALSE) -> 0 | AG13: =VLOOKUP($A13,'TABLA DINAMICA PARCIAL 3'!$A$5:$I$768,3,FALSE) -> 10 | AH13: =VLOOKUP($A13,'TABLA DINAMICA PARCIAL 3'!$A$5:$I$768,4,FALSE) -> 0 | AI13: =VLOOKUP($A13,'TABLA DINAMICA PARCIAL 3'!$A$5:$I$768,5,FALSE) -> 0 | AJ13: =VLOOKUP($A13,'TABLA DINAMICA PARCIAL 3'!$A$5:$I$768,6,FALSE) -> 0 | AK13: =VLOOKUP($A13,'TABLA DINAMICA PARCIAL 3'!$A$5:$I$768,7,FALSE) -> 10 | AL13: =VLOOKUP($A13,'TABLA DINAMICA PARCIAL 3'!$A$5:$I$768,8,FALSE) -> 0 | AM13: =SUM(AF13:AL13) -> 20 | AN13: =VLOOKUP($A13,'TABLA DINAMICA PARCIAL 4'!$A$5:$F$760,2,FALSE) -> 0 | AO13: =VLOOKUP($A13,'TABLA DINAMICA PARCIAL 4'!$A$5:$F$760,3,FALSE) -> 0 | AP13: =VLOOKUP($A13,'TABLA DINAMICA PARCIAL 4'!$A$5:$F$760,4,FALSE) -> 0 | AQ13: =VLOOKUP($A13,'TABLA DINAMICA PARCIAL 4'!$A$5:$F$760,5,FALSE) -> 0 | AR13: =VLOOKUP($A13,'TABLA DINAMICA PARCIAL 4'!$A$5:$F$760,6,FALSE) -> 10 | AS13: =SUM(AN13:AR13) -> 10 | AT13: =VLOOKUP($A13,'USUARIOS Y GRUPO'!$A$2:$D$851,4,FALSE) -> P19-MAT1022-10
A14: 163297 | B14: Cabrera Soberanes | C14: Oliver | D14: =VLOOKUP($A14,'TABLA DINAM PARCIAL 1'!$A$5:$I$793,2,FALSE) -> 0 | E14: =VLOOKUP(A14,'TABLA DINAM PARCIAL 1'!A425:I1213,3,FALSE) -> 10 | F14: =VLOOKUP(A14,'TABLA DINAM PARCIAL 1'!A425:I1213,4,FALSE) -> 0 | G14: =VLOOKUP(A14,'TABLA DINAM PARCIAL 1'!A425:I1213,5,FALSE) -> 0 | H14: =VLOOKUP(A14,'TABLA DINAM PARCIAL 1'!A425:I1213,6,FALSE) -> 0 | I14: =VLOOKUP(A14,'TABLA DINAM PARCIAL 1'!A425:I1213,7,FALSE) -> 0 | J14: =VLOOKUP(A14,'TABLA DINAM PARCIAL 1'!A425:I1213,8,FALSE) -> 10 | K14: =VLOOKUP(A14,'TABLA DINAM PARCIAL 1'!A425:I1213,9,FALSE) -> 0 | L14: =SUM(D14:K14) -> 20 | M14: =VLOOKUP($A14,'TABLA DINAMICA PARCIAL 2'!$A$5:$T$772,2,FALSE) -> 0 | N14: =VLOOKUP($A14,'TABLA DINAMICA PARCIAL 2'!$A$5:$T$772,3,FALSE) -> 0 | O14: =VLOOKUP($A14,'TABLA DINAMICA PARCIAL 2'!$A$5:$T$772,4,FALSE) -> 0 | P14: =VLOOKUP($A14,'TABLA DINAMICA PARCIAL 2'!$A$5:$T$772,5,FALSE) -> 0 | Q14: =VLOOKUP($A14,'TABLA DINAMICA PARCIAL 2'!$A$5:$T$772,6,FALSE) -> 0 | R14: =VLOOKUP($A14,'TABLA DINAMICA PARCIAL 2'!$A$5:$T$772,7,FALSE) -> 0 | S14: =VLOOKUP($A14,'TABLA DINAMICA PARCIAL 2'!$A$5:$T$772,8,FALSE) -> 0 | T14: =VLOOKUP($A14,'TABLA DINAMICA PARCIAL 2'!$A$5:$T$772,9,FALSE) -> 0 | U14: =VLOOKUP($A14,'TABLA DINAMICA PARCIAL 2'!$A$5:$T$772,10,FALSE) -> 10 | V14: =VLOOKUP($A14,'TABLA DINAMICA PARCIAL 2'!$A$5:$T$772,11,FALSE) -> 0 | W14: =VLOOKUP($A14,'TABLA DINAMICA PARCIAL 2'!$A$5:$T$772,12,FALSE) -> 0 | X14: =VLOOKUP($A14,'TABLA DINAMICA PARCIAL 2'!$A$5:$T$772,13,FALSE) -> 0 | Y14: =VLOOKUP($A14,'TABLA DINAMICA PARCIAL 2'!$A$5:$T$772,14,FALSE) -> 0 | Z14: =VLOOKUP($A14,'TABLA DINAMICA PARCIAL 2'!$A$5:$T$772,15,FALSE) -> 10 | AA14: =VLOOKUP($A14,'TABLA DINAMICA PARCIAL 2'!$A$5:$T$772,16,FALSE) -> 0 | AB14: =VLOOKUP(I14,'TABLA DINAMICA PARCIAL 2'!I464:AB1235,17,FALSE) -> 0 | AC14: =VLOOKUP(I14,'TABLA DINAMICA PARCIAL 2'!I464:AB1235,18,FALSE) -> 0 | AD14: =VLOOKUP(I14,'TABLA DINAMICA PARCIAL 2'!I464:AB1235,19,FALSE) -> 0 | AE14: =SUM(M14:AD14) -> 20 | AF14: =VLOOKUP($A14,'TABLA DINAMICA PARCIAL 3'!$A$5:$I$768,2,FALSE) -> 10 | AG14: =VLOOKUP($A14,'TABLA DINAMICA PARCIAL 3'!$A$5:$I$768,3,FALSE) -> 0 | AH14: =VLOOKUP($A14,'TABLA DINAMICA PARCIAL 3'!$A$5:$I$768,4,FALSE) -> 0 | AI14: =VLOOKUP($A14,'TABLA DINAMICA PARCIAL 3'!$A$5:$I$768,5,FALSE) -> 0 | AJ14: =VLOOKUP($A14,'TABLA DINAMICA PARCIAL 3'!$A$5:$I$768,6,FALSE) -> 10 | AK14: =VLOOKUP($A14,'TABLA DINAMICA PARCIAL 3'!$A$5:$I$768,7,FALSE) -> 10 | AL14: =VLOOKUP($A14,'TABLA DINAMICA PARCIAL 3'!$A$5:$I$768,8,FALSE) -> 0 | AM14: =SUM(AF14:AL14) -> 30 | AN14: =VLOOKUP($A14,'TABLA DINAMICA PARCIAL 4'!$A$5:$F$760,2,FALSE) -> 0 | AO14: =VLOOKUP($A14,'TABLA DINAMICA PARCIAL 4'!$A$5:$F$760,3,FALSE) -> 0 | AP14: =VLOOKUP($A14,'TABLA DINAMICA PARCIAL 4'!$A$5:$F$760,4,FALSE) -> 0 | AQ14: =VLOOKUP($A14,'TABLA DINAMICA PARCIAL 4'!$A$5:$F$760,5,FALSE) -> 0 | AR14: =VLOOKUP($A14,'TABLA DINAMICA PARCIAL 4'!$A$5:$F$760,6,FALSE) -> 10 | AS14: =SUM(AN14:AR14) -> 10 | AT14: =VLOOKUP($A14,'USUARIOS Y GRUPO'!$A$2:$D$851,4,FALSE) -> P19-MAT1022-10
A15: 163811 | B15: Ricárdez Aguilar | C15: Sebastián | D15: =VLOOKUP($A15,'TABLA DINAM PARCIAL 1'!$A$5:$I$793,2,FALSE) -> 0 | E15: =VLOOKUP(A15,'TABLA DINAM PARCIAL 1'!A557:I1345,3,FALSE) -> 0 | F15: =VLOOKUP(A15,'TABLA DINAM PARCIAL 1'!A557:I1345,4,FALSE) -> 0 | G15: =VLOOKUP(A15,'TABLA DINAM PARCIAL 1'!A557:I1345,5,FALSE) -> 10 | H15: =VLOOKUP(A15,'TABLA DINAM PARCIAL 1'!A557:I1345,6,FALSE) -> 0 | I15: =VLOOKUP(A15,'TABLA DINAM PARCIAL 1'!A557:I1345,7,FALSE) -> 0 | J15: =VLOOKUP(A15,'TABLA DINAM PARCIAL 1'!A557:I1345,8,FALSE) -> 10 | K15: =VLOOKUP(A15,'TABLA DINAM PARCIAL 1'!A557:I1345,9,FALSE) -> 0 | L15: =SUM(D15:K15) -> 20 | M15: =VLOOKUP($A15,'TABLA DINAMICA PARCIAL 2'!$A$5:$T$772,2,FALSE) -> 0 | N15: =VLOOKUP($A15,'TABLA DINAMICA PARCIAL 2'!$A$5:$T$772,3,FALSE) -> 0 | O15: =VLOOKUP($A15,'TABLA DINAMICA PARCIAL 2'!$A$5:$T$772,4,FALSE) -> 10 | P15: =VLOOKUP($A15,'TABLA DINAMICA PARCIAL 2'!$A$5:$T$772,5,FALSE) -> 0 | Q15: =VLOOKUP($A15,'TABLA DINAMICA PARCIAL 2'!$A$5:$T$772,6,FALSE) -> 0 | R15: =VLOOKUP($A15,'TABLA DINAMICA PARCIAL 2'!$A$5:$T$772,7,FALSE) -> 10 | S15: =VLOOKUP($A15,'TABLA DINAMICA PARCIAL 2'!$A$5:$T$772,8,FALSE) -> 0 | T15: =VLOOKUP($A15,'TABLA DINAMICA PARCIAL 2'!$A$5:$T$772,9,FALSE) -> 0 | U15: =VLOOKUP($A15,'TABLA DINAMICA PARCIAL 2'!$A$5:$T$772,10,FALSE) -> 0 | V15: =VLOOKUP($A15,'TABLA DINAMICA PARCIAL 2'!$A$5:$T$772,11,FALSE) -> 0 | W15: =VLOOKUP($A15,'TABLA DINAMICA PARCIAL 2'!$A$5:$T$772,12,FALSE) -> 0 | X15: =VLOOKUP($A15,'TABLA DINAMICA PARCIAL 2'!$A$5:$T$772,13,FALSE) -> 0 | Y15: =VLOOKUP($A15,'TABLA DINAMICA PARCIAL 2'!$A$5:$T$772,14,FALSE) -> 0 | Z15: =VLOOKUP($A15,'TABLA DINAMICA PARCIAL 2'!$A$5:$T$772,15,FALSE) -> 10 | AA15: =VLOOKUP($A15,'TABLA DINAMICA PARCIAL 2'!$A$5:$T$772,16,FALSE) -> 0 | AB15: =VLOOKUP(I15,'TABLA DINAMICA PARCIAL 2'!I604:AB1375,17,FALSE) -> 0 | AC15: =VLOOKUP(I15,'TABLA DINAMICA PARCIAL 2'!I604:AB1375,18,FALSE) -> 0 | AD15: =VLOOKUP(I15,'TABLA DINAMICA PARCIAL 2'!I604:AB1375,19,FALSE) -> 0 | AE15: =SUM(M15:AD15) -> 30 | AF15: =VLOOKUP($A15,'TABLA DINAMICA PARCIAL 3'!$A$5:$I$768,2,FALSE) -> 10 | AG15: =VLOOKUP($A15,'TABLA DINAMICA PARCIAL 3'!$A$5:$I$768,3,FALSE) -> 0 | AH15: =VLOOKUP($A15,'TABLA DINAMICA PARCIAL 3'!$A$5:$I$768,4,FALSE) -> 10 | AI15: =VLOOKUP($A15,'TABLA DINAMICA PARCIAL 3'!$A$5:$I$768,5,FALSE) -> 0 | AJ15: =VLOOKUP($A15,'TABLA DINAMICA PARCIAL 3'!$A$5:$I$768,6,FALSE) -> 0 | AK15: =VLOOKUP($A15,'TABLA DINAMICA PARCIAL 3'!$A$5:$I$768,7,FALSE) -> 0 | AL15: =VLOOKUP($A15,'TABLA DINAMICA PARCIAL 3'!$A$5:$I$768,8,FALSE) -> 0 | AM15: =SUM(AF15:AL15) -> 20 | AN15: =VLOOKUP($A15,'TABLA DINAMICA PARCIAL 4'!$A$5:$F$760,2,FALSE) -> 0 | AO15: =VLOOKUP($A15,'TABLA DINAMICA PARCIAL 4'!$A$5:$F$760,3,FALSE) -> 0 | AP15: =VLOOKUP($A15,'TABLA DINAMICA PARCIAL 4'!$A$5:$F$760,4,FALSE) -> 0 | AQ15: =VLOOKUP($A15,'TABLA DINAMICA PARCIAL 4'!$A$5:$F$760,5,FALSE) -> 10 | AR15: =VLOOKUP($A15,'TABLA DINAMICA PARCIAL 4'!$A$5:$F$760,6,FALSE) -> 10 | AS15: =SUM(AN15:AR15) -> 20 | AT15: =VLOOKUP($A15,'USUARIOS Y GRUPO'!$A$2:$D$851,4,FALSE) -> P19-MAT1022-10
A16: 163838 | B16: Manchinelly Mota | C16: Michelle | D16: =VLOOKUP($A16,'TABLA DINAM PARCIAL 1'!$A$5:$I$793,2,FALSE) -> 10 | E16: =VLOOKUP(A16,'TABLA DINAM PARCIAL 1'!A559:I1347,3,FALSE) -> 0 | F16: =VLOOKUP(A16,'TABLA DINAM PARCIAL 1'!A559:I1347,4,FALSE) -> 10 | G16: =VLOOKUP(A16,'TABLA DINAM PARCIAL 1'!A559:I1347,5,FALSE) -> 0 | H16: =VLOOKUP(A16,'TABLA DINAM PARCIAL 1'!A559:I1347,6,FALSE) -> 0 | I16: =VLOOKUP(A16,'TABLA DINAM PARCIAL 1'!A559:I1347,7,FALSE) -> 0 | J16: =VLOOKUP(A16,'TABLA DINAM PARCIAL 1'!A559:I1347,8,FALSE) -> 0 | K16: =VLOOKUP(A16,'TABLA DINAM PARCIAL 1'!A559:I1347,9,FALSE) -> 0 | L16: =SUM(D16:K16) -> 20 | M16: =VLOOKUP($A16,'TABLA DINAMICA PARCIAL 2'!$A$5:$T$772,2,FALSE) -> 0 | N16: =VLOOKUP($A16,'TABLA DINAMICA PARCIAL 2'!$A$5:$T$772,3,FALSE) -> 0 | O16: =VLOOKUP($A16,'TABLA DINAMICA PARCIAL 2'!$A$5:$T$772,4,FALSE) -> 0 | P16: =VLOOKUP($A16,'TABLA DINAMICA PARCIAL 2'!$A$5:$T$772,5,FALSE) -> 0 | Q16: =VLOOKUP($A16,'TABLA DINAMICA PARCIAL 2'!$A$5:$T$772,6,FALSE) -> 0 | R16: =VLOOKUP($A16,'TABLA DINAMICA PARCIAL 2'!$A$5:$T$772,7,FALSE) -> 0 | S16: =VLOOKUP($A16,'TABLA DINAMICA PARCIAL 2'!$A$5:$T$772,8,FALSE) -> 0 | T16: =VLOOKUP($A16,'TABLA DINAMICA PARCIAL 2'!$A$5:$T$772,9,FALSE) -> 0 | U16: =VLOOKUP($A16,'TABLA DINAMICA PARCIAL 2'!$A$5:$T$772,10,FALSE) -> 0 | V16: =VLOOKUP($A16,'TABLA DINAMICA PARCIAL 2'!$A$5:$T$772,11,FALSE) -> 0 | W16: =VLOOKUP($A16,'TABLA DINAMICA PARCIAL 2'!$A$5:$T$772,12,FALSE) -> 0 | X16: =VLOOKUP($A16,'TABLA DINAMICA PARCIAL 2'!$A$5:$T$772,13,FALSE) -> 0 | Y16: =VLOOKUP($A16,'TABLA DINAMICA PARCIAL 2'!$A$5:$T$772,14,FALSE) -> 10 | Z16: =VLOOKUP($A16,'TABLA DINAMICA PARCIAL 2'!$A$5:$T$772,15,FALSE) -> 0 | AA16: =VLOOKUP($A16,'TABLA DINAMICA PARCIAL 2'!$A$5:$T$772,16,FALSE) -> 0 | AB16: =VLOOKUP(I16,'TABLA DINAMICA PARCIAL 2'!I606:AB1377,17,FALSE) -> 0 | AC16: =VLOOKUP(I16,'TABLA DINAMICA PARCIAL 2'!I606:AB1377,18,FALSE) -> 0 | AD16: =VLOOKUP(I16,'TABLA DINAMICA PARCIAL 2'!I606:AB1377,19,FALSE) -> 0 | AE16: =SUM(M16:AD16) -> 10 | AF16: =VLOOKUP($A16,'TABLA DINAMICA PARCIAL 3'!$A$5:$I$768,2,FALSE) -> 10 | AG16: =VLOOKUP($A16,'TABLA DINAMICA PARCIAL 3'!$A$5:$I$768,3,FALSE) -> 0 | AH16: =VLOOKUP($A16,'TABLA DINAMICA PARCIAL 3'!$A$5:$I$768,4,FALSE) -> 10 | AI16: =VLOOKUP($A16,'TABLA DINAMICA PARCIAL 3'!$A$5:$I$768,5,FALSE) -> 0 | AJ16: =VLOOKUP($A16,'TABLA DINAMICA PARCIAL 3'!$A$5:$I$768,6,FALSE) -> 0 | AK16: =VLOOKUP($A16,'TABLA DINAMICA PARCIAL 3'!$A$5:$I$768,7,FALSE) -> 0 | AL16: =VLOOKUP($A16,'TABLA DINAMICA PARCIAL 3'!$A$5:$I$768,8,FALSE) -> 0 | AM16: =SUM(AF16:AL16) -> 20 | AN16: =VLOOKUP($A16,'TABLA DINAMICA PARCIAL 4'!$A$5:$F$760,2,FALSE) -> 0 | AO16: =VLOOKUP($A16,'TABLA DINAMICA PARCIAL 4'!$A$5:$F$760,3,FALSE) -> 0 | AP16: =VLOOKUP($A16,'TABLA DINAMICA PARCIAL 4'!$A$5:$F$760,4,FALSE) -> 0 | AQ16: =VLOOKUP($A16,'TABLA DINAMICA PARCIAL 4'!$A$5:$F$760,5,FALSE) -> 10 | AR16: =VLOOKUP($A16,'TABLA DINAMICA PARCIAL 4'!$A$5:$F$760,6,FALSE) -> 10 | AS16: =SUM(AN16:AR16) -> 20 | AT16: =VLOOKUP($A16,'USUARIOS Y GRUPO'!$A$2:$D$851,4,FALSE) -> P19-MAT1022-10
A17: 164112 | B17: Flores Marín | C17: Erick | D17: =VLOOKUP($A17,'TABLA DINAM PARCIAL 1'!$A$5:$I$793,2,FALSE) -> 0 | E17: =VLOOKUP(A17,'TABLA DINAM PARCIAL 1'!A619:I1407,3,FALSE) -> 0 | F17: =VLOOKUP(A17,'TABLA DINAM PARCIAL 1'!A619:I1407,4,FALSE) -> 0 | G17: =VLOOKUP(A17,'TABLA DINAM PARCIAL 1'!A619:I1407,5,FALSE) -> 10 | H17: =VLOOKUP(A17,'TABLA DINAM PARCIAL 1'!A619:I1407,6,FALSE) -> 0 | I17: =VLOOKUP(A17,'TABLA DINAM PARCIAL 1'!A619:I1407,7,FALSE) -> 0 | J17: =VLOOKUP(A17,'TABLA DINAM PARCIAL 1'!A619:I1407,8,FALSE) -> 0 | K17: =VLOOKUP(A17,'TABLA DINAM PARCIAL 1'!A619:I1407,9,FALSE) -> 10 | L17: =SUM(D17:K17) -> 20 | M17: =VLOOKUP($A17,'TABLA DINAMICA PARCIAL 2'!$A$5:$T$772,2,FALSE) -> 0 | N17: =VLOOKUP($A17,'TABLA DINAMICA PARCIAL 2'!$A$5:$T$772,3,FALSE) -> 0 | O17: =VLOOKUP($A17,'TABLA DINAMICA PARCIAL 2'!$A$5:$T$772,4,FALSE) -> 0 | P17: =VLOOKUP($A17,'TABLA DINAMICA PARCIAL 2'!$A$5:$T$772,5,FALSE) -> 0 | Q17: =VLOOKUP($A17,'TABLA DINAMICA PARCIAL 2'!$A$5:$T$772,6,FALSE) -> 0 | R17: =VLOOKUP($A17,'TABLA DINAMICA PARCIAL 2'!$A$5:$T$772,7,FALSE) -> 0 | S17: =VLOOKUP($A17,'TABLA DINAMICA PARCIAL 2'!$A$5:$T$772,8,FALSE) -> 0 | T17: =VLOOKUP($A17,'TABLA DINAMICA PARCIAL 2'!$A$5:$T$772,9,FALSE) -> 0 | U17: =VLOOKUP($A17,'TABLA DINAMICA PARCIAL 2'!$A$5:$T$772,10,FALSE) -> 0 | V17: =VLOOKUP($A17,'TABLA DINAMICA PARCIAL 2'!$A$5:$T$772,11,FALSE) -> 10 | W17: =VLOOKUP($A17,'TABLA DINAMICA PARCIAL 2'!$A$5:$T$772,12,FALSE) -> 0 | X17: =VLOOKUP($A17,'TABLA DINAMICA PARCIAL 2'!$A$5:$T$772,13,FALSE) -> 0 | Y17: =VLOOKUP($A17,'TABLA DINAMICA PARCIAL 2'!$A$5:$T$772,14,FALSE) -> 0 | Z17: =VLOOKUP($A17,'TABLA DINAMICA PARCIAL 2'!$A$5:$T$772,15,FALSE) -> 0 | AA17: =VLOOKUP($A17,'TABLA DINAMICA PARCIAL 2'!$A$5:$T$772,16,FALSE) -> 10 | AB17: =VLOOKUP(I17,'TABLA DINAMICA PARCIAL 2'!I670:AB1441,17,FALSE) -> 0 | AC17: =VLOOKUP(I17,'TABLA DINAMICA PARCIAL 2'!I670:AB1441,18,FALSE) -> 0 | AD17: =VLOOKUP(I17,'TABLA DINAMICA PARCIAL 2'!I670:AB1441,19,FALSE) -> 0 | AE17: =SUM(M17:AD17) -> 20 | AF17: =VLOOKUP($A17,'TABLA DINAMICA PARCIAL 3'!$A$5:$I$768,2,FALSE) -> 10 | AG17: =VLOOKUP($A17,'TABLA DINAMICA PARCIAL 3'!$A$5:$I$768,3,FALSE) -> 0 | AH17: =VLOOKUP($A17,'TABLA DINAMICA PARCIAL 3'!$A$5:$I$768,4,FALSE) -> 0 | AI17: =VLOOKUP($A17,'TABLA DINAMICA PARCIAL 3'!$A$5:$I$768,5,FALSE) -> 0 | AJ17: =VLOOKUP($A17,'TABLA DINAMICA PARCIAL 3'!$A$5:$I$768,6,FALSE) -> 0 | AK17: =VLOOKUP($A17,'TABLA DINAMICA PARCIAL 3'!$A$5:$I$768,7,FALSE) -> 0 | AL17: =VLOOKUP($A17,'TABLA DINAMICA PARCIAL 3'!$A$5:$I$768,8,FALSE) -> 10 | AM17: =SUM(AF17:AL17) -> 20 | AN17: =VLOOKUP($A17,'TABLA DINAMICA PARCIAL 4'!$A$5:$F$760,2,FALSE) -> 0 | AO17: =VLOOKUP($A17,'TABLA DINAMICA PARCIAL 4'!$A$5:$F$760,3,FALSE) -> 0 | AP17: =VLOOKUP($A17,'TABLA DINAMICA PARCIAL 4'!$A$5:$F$760,4,FALSE) -> 0 | AQ17: =VLOOKUP($A17,'TABLA DINAMICA PARCIAL 4'!$A$5:$F$760,5,FALSE) -> 0 | AR17: =VLOOKUP($A17,'TABLA DINAMICA PARCIAL 4'!$A$5:$F$760,6,FALSE) -> 10 | AS17: =SUM(AN17:AR17) -> 10 | AT17: =VLOOKUP($A17,'USUARIOS Y GRUPO'!$A$2:$D$851,4,FALSE) -> P19-MAT1022-10
A18: 164117 | B18: Xochicale Alvarez | C18: Hugo | D18: =VLOOKUP($A18,'TABLA DINAM PARCIAL 1'!$A$5:$I$793,2,FALSE) -> 0 | E18: =VLOOKUP(A18,'TABLA DINAM PARCIAL 1'!A623:I1411,3,FALSE) -> 0 | F18: =VLOOKUP(A18,'TABLA DINAM PARCIAL 1'!A623:I1411,4,FALSE) -> 0 | G18: =VLOOKUP(A18,'TABLA DINAM PARCIAL 1'!A623:I1411,5,FALSE) -> 0 | H18: =VLOOKUP(A18,'TABLA DINAM PARCIAL 1'!A623:I1411,6,FALSE) -> 10 | I18: =VLOOKUP(A18,'TABLA DINAM PARCIAL 1'!A623:I1411,7,FALSE) -> 0 | J18: =VLOOKUP(A18,'TABLA DINAM PARCIAL 1'!A623:I1411,8,FALSE) -> 0 | K18: =VLOOKUP(A18,'TABLA DINAM PARCIAL 1'!A623:I1411,9,FALSE) -> 10 | L18: =SUM(D18:K18) -> 20 | M18: =VLOOKUP($A18,'TABLA DINAMICA PARCIAL 2'!$A$5:$T$772,2,FALSE) -> 0 | N18: =VLOOKUP($A18,'TABLA DINAMICA PARCIAL 2'!$A$5:$T$772,3,FALSE) -> 0 | O18: =VLOOKUP($A18,'TABLA DINAMICA PARCIAL 2'!$A$5:$T$772,4,FALSE) -> 0 | P18: =VLOOKUP($A18,'TABLA DINAMICA PARCIAL 2'!$A$5:$T$772,5,FALSE) -> 0 | Q18: =VLOOKUP($A18,'TABLA DINAMICA PARCIAL 2'!$A$5:$T$772,6,FALSE) -> 0 | R18: =VLOOKUP($A18,'TABLA DINAMICA PARCIAL 2'!$A$5:$T$772,7,FALSE) -> 0 | S18: =VLOOKUP($A18,'TABLA DINAMICA PARCIAL 2'!$A$5:$T$772,8,FALSE) -> 0 | T18: =VLOOKUP($A18,'TABLA DINAMICA PARCIAL 2'!$A$5:$T$772,9,FALSE) -> 10 | U18: =VLOOKUP($A18,'TABLA DINAMICA PARCIAL 2'!$A$5:$T$772,10,FALSE) -> 0 | V18: =VLOOKUP($A18,'TABLA DINAMICA PARCIAL 2'!$A$5:$T$772,11,FALSE) -> 0 | W18: =VLOOKUP($A18,'TABLA DINAMICA PARCIAL 2'!$A$5:$T$772,12,FALSE) -> 0 | X18: =VLOOKUP($A18,'TABLA DINAMICA PARCIAL 2'!$A$5:$T$772,13,FALSE) -> 0 | Y18: =VLOOKUP($A18,'TABLA DINAMICA PARCIAL 2'!$A$5:$T$772,14,FALSE) -> 0 | Z18: =VLOOKUP($A18,'TABLA DINAMICA PARCIAL 2'!$A$5:$T$772,15,FALSE) -> 0 | AA18: =VLOOKUP($A18,'TABLA DINAMICA PARCIAL 2'!$A$5:$T$772,16,FALSE) -> 0 | AB18: =VLOOKUP(I18,'TABLA DINAMICA PARCIAL 2'!I674:AB1445,17,FALSE) -> 0 | AC18: =VLOOKUP(I18,'TABLA DINAMICA PARCIAL 2'!I674:AB1445,18,FALSE) -> 0 | AD18: =VLOOKUP(I18,'TABLA DINAMICA PARCIAL 2'!I674:AB1445,19,FALSE) -> 0 | AE18: =SUM(M18:AD18) -> 10 | AF18: =VLOOKUP($A18,'TABLA DINAMICA PARCIAL 3'!$A$5:$I$768,2,FALSE) -> 0 | AG18: =VLOOKUP($A18,'TABLA DINAMICA PARCIAL 3'!$A$5:$I$768,3,FALSE) -> 0 | AH18: =VLOOKUP($A18,'TABLA DINAMICA PARCIAL 3'!$A$5:$I$768,4,FALSE) -> 10 | AI18: =VLOOKUP($A18,'TABLA DINAMICA PARCIAL 3'!$A$5:$I$768,5,FALSE) -> 0 | AJ18: =VLOOKUP($A18,'TABLA DINAMICA PARCIAL 3'!$A$5:$I$768,6,FALSE) -> 0 | AK18: =VLOOKUP($A18,'TABLA DINAMICA PARCIAL 3'!$A$5:$I$768,7,FALSE) -> 0 | AL18: =VLOOKUP($A18,'TABLA DINAMICA PARCIAL 3'!$A$5:$I$768,8,FALSE) -> 0 | AM18: =SUM(AF18:AL18) -> 10 | AN18: =VLOOKUP($A18,'TABLA DINAMICA PARCIAL 4'!$A$5:$F$760,2,FALSE) -> 10 | AO18: =VLOOKUP($A18,'TABLA DINAMICA PARCIAL 4'!$A$5:$F$760,3,FALSE) -> 0 | AP18: =VLOOKUP($A18,'TABLA DINAMICA PARCIAL 4'!$A$5:$F$760,4,FALSE) -> 0 | AQ18: =VLOOKUP($A18,'TABLA DINAMICA PARCIAL 4'!$A$5:$F$760,5,FALSE) -> 0 | AR18: =VLOOKUP($A18,'TABLA DINAMICA PARCIAL 4'!$A$5:$F$760,6,FALSE) -> 0 | AS18: =SUM(AN18:AR18) -> 10 | AT18: =VLOOKUP($A18,'USUARIOS Y GRUPO'!$A$2:$D$851,4,FALSE) -> P19-MAT1022-10
A19: 164709 | B19: Bernardi Zanatta | C19: Miguel | D19: =VLOOKUP($A19,'TABLA DINAM PARCIAL 1'!$A$5:$I$793,2,FALSE) -> 0 | E19: =VLOOKUP(A19,'TABLA DINAM PARCIAL 1'!A752:I1540,3,FALSE) -> 0 | F19: =VLOOKUP(A19,'TABLA DINAM PARCIAL 1'!A752:I1540,4,FALSE) -> 0 | G19: =VLOOKUP(A19,'TABLA DINAM PARCIAL 1'!A752:I1540,5,FALSE) -> 0 | H19: =VLOOKUP(A19,'TABLA DINAM PARCIAL 1'!A752:I1540,6,FALSE) -> 0 | I19: =VLOOKUP(A19,'TABLA DINAM PARCIAL 1'!A752:I1540,7,FALSE) -> 10 | J19: =VLOOKUP(A19,'TABLA DINAM PARCIAL 1'!A752:I1540,8,FALSE) -> 10 | K19: =VLOOKUP(A19,'TABLA DINAM PARCIAL 1'!A752:I1540,9,FALSE) -> 0 | L19: =SUM(D19:K19) -> 20 | M19: =VLOOKUP($A19,'TABLA DINAMICA PARCIAL 2'!$A$5:$T$772,2,FALSE) -> 0 | N19: =VLOOKUP($A19,'TABLA DINAMICA PARCIAL 2'!$A$5:$T$772,3,FALSE) -> 0 | O19: =VLOOKUP($A19,'TABLA DINAMICA PARCIAL 2'!$A$5:$T$772,4,FALSE) -> 0 | P19: =VLOOKUP($A19,'TABLA DINAMICA PARCIAL 2'!$A$5:$T$772,5,FALSE) -> 0 | Q19: =VLOOKUP($A19,'TABLA DINAMICA PARCIAL 2'!$A$5:$T$772,6,FALSE) -> 0 | R19: =VLOOKUP($A19,'TABLA DINAMICA PARCIAL 2'!$A$5:$T$772,7,FALSE) -> 0 | S19: =VLOOKUP($A19,'TABLA DINAMICA PARCIAL 2'!$A$5:$T$772,8,FALSE) -> 0 | T19: =VLOOKUP($A19,'TABLA DINAMICA PARCIAL 2'!$A$5:$T$772,9,FALSE) -> 0 | U19: =VLOOKUP($A19,'TABLA DINAMICA PARCIAL 2'!$A$5:$T$772,10,FALSE) -> 10 | V19: =VLOOKUP($A19,'TABLA DINAMICA PARCIAL 2'!$A$5:$T$772,11,FALSE) -> 0 | W19: =VLOOKUP($A19,'TABLA DINAMICA PARCIAL 2'!$A$5:$T$772,12,FALSE) -> 0 | X19: =VLOOKUP($A19,'TABLA DINAMICA PARCIAL 2'!$A$5:$T$772,13,FALSE) -> 0 | Y19: =VLOOKUP($A19,'TABLA DINAMICA PARCIAL 2'!$A$5:$T$772,14,FALSE) -> 0 | Z19: =VLOOKUP($A19,'TABLA DINAMICA PARCIAL 2'!$A$5:$T$772,15,FALSE) -> 0 | AA19: =VLOOKUP($A19,'TABLA DINAMICA PARCIAL 2'!$A$5:$T$772,16,FALSE) -> 0 | AB19: =VLOOKUP(I19,'TABLA DINAMICA PARCIAL 2'!I813:AB1584,17,FALSE) -> #N/A | AC19: =VLOOKUP(I19,'TABLA DINAMICA PARCIAL 2'!I813:AB1584,18,FALSE) -> #N/A | AD19: =VLOOKUP(I19,'TABLA DINAMICA PARCIAL 2'!I813:AB1584,19,FALSE) -> #N/A | AE19: =SUM(M19:AD19) -> #N/A | AF19: =VLOOKUP($A19,'TABLA DINAMICA PARCIAL 3'!$A$5:$I$768,2,FALSE) -> 0 | AG19: =VLOOKUP($A19,'TABLA DINAMICA PARCIAL 3'!$A$5:$I$768,3,FALSE) -> 0 | AH19: =VLOOKUP($A19,'TABLA DINAMICA PARCIAL 3'!$A$5:$I$768,4,FALSE) -> 0 | AI19: =VLOOKUP($A19,'TABLA DINAMICA PARCIAL 3'!$A$5:$I$768,5,FALSE) -> 0 | AJ19: =VLOOKUP($A19,'TABLA DINAMICA PARCIAL 3'!$A$5:$I$768,6,FALSE) -> 0 | AK19: =VLOOKUP($A19,'TABLA DINAMICA PARCIAL 3'!$A$5:$I$768,7,FALSE) -> 0 | AL19: =VLOOKUP($A19,'TABLA DINAMICA PARCIAL 3'!$A$5:$I$768,8,FALSE) -> 0 | AM19: =SUM(AF19:AL19) -> 0 | AN19: =VLOOKUP($A19,'TABLA DINAMICA PARCIAL 4'!$A$5:$F$760,2,FALSE) -> 0 | AO19: =VLOOKUP($A19,'TABLA DINAMICA PARCIAL 4'!$A$5:$F$760,3,FALSE) -> 10 | AP19: =VLOOKUP($A19,'TABLA DINAMICA PARCIAL 4'!$A$5:$F$760,4,FALSE) -> 0 | AQ19: =VLOOKUP($A19,'TABLA DINAMICA PARCIAL 4'!$A$5:$F$760,5,FALSE) -> 0 | AR19: =VLOOKUP($A19,'TABLA DINAMICA PARCIAL 4'!$A$5:$F$760,6,FALSE) -> 10 | AS19: =SUM(AN19:AR19) -> 20 | AT19: =VLOOKUP($A19,'USUARIOS Y GRUPO'!$A$2:$D$851,4,FALSE) -> P19-MAT1022-10
A20: 164720 | B20: Peña Lomelí | C20: Alondra | D20: =VLOOKUP($A20,'TABLA DINAM PARCIAL 1'!$A$5:$I$793,2,FALSE) -> 0 | E20: =VLOOKUP(A20,'TABLA DINAM PARCIAL 1'!A754:I1542,3,FALSE) -> 10 | F20: =VLOOKUP(A20,'TABLA DINAM PARCIAL 1'!A754:I1542,4,FALSE) -> 0 | G20: =VLOOKUP(A20,'TABLA DINAM PARCIAL 1'!A754:I1542,5,FALSE) -> 0 | H20: =VLOOKUP(A20,'TABLA DINAM PARCIAL 1'!A754:I1542,6,FALSE) -> 0 | I20: =VLOOKUP(A20,'TABLA DINAM PARCIAL 1'!A754:I1542,7,FALSE) -> 0 | J20: =VLOOKUP(A20,'TABLA DINAM PARCIAL 1'!A754:I1542,8,FALSE) -> 10 | K20: =VLOOKUP(A20,'TABLA DINAM PARCIAL 1'!A754:I1542,9,FALSE) -> 0 | L20: =SUM(D20:K20) -> 20 | M20: =VLOOKUP($A20,'TABLA DINAMICA PARCIAL 2'!$A$5:$T$772,2,FALSE) -> 0 | N20: =VLOOKUP($A20,'TABLA DINAMICA PARCIAL 2'!$A$5:$T$772,3,FALSE) -> 0 | O20: =VLOOKUP($A20,'TABLA DINAMICA PARCIAL 2'!$A$5:$T$772,4,FALSE) -> 0 | P20: =VLOOKUP($A20,'TABLA DINAMICA PARCIAL 2'!$A$5:$T$772,5,FALSE) -> 0 | Q20: =VLOOKUP($A20,'TABLA DINAMICA PARCIAL 2'!$A$5:$T$772,6,FALSE) -> 0 | R20: =VLOOKUP($A20,'TABLA DINAMICA PARCIAL 2'!$A$5:$T$772,7,FALSE) -> 0 | S20: =VLOOKUP($A20,'TABLA DINAMICA PARCIAL 2'!$A$5:$T$772,8,FALSE) -> 0 | T20: =VLOOKUP($A20,'TABLA DINAMICA PARCIAL 2'!$A$5:$T$772,9,FALSE) -> 0 | U20: =VLOOKUP($A20,'TABLA DINAMICA PARCIAL 2'!$A$5:$T$772,10,FALSE) -> 0 | V20: =VLOOKUP($A20,'TABLA DINAMICA PARCIAL 2'!$A$5:$T$772,11,FALSE) -> 0 | W20: =VLOOKUP($A20,'TABLA DINAMICA PARCIAL 2'!$A$5:$T$772,12,FALSE) -> 0 | X20: =VLOOKUP($A20,'TABLA DINAMICA PARCIAL 2'!$A$5:$T$772,13,FALSE) -> 0 | Y20: =VLOOKUP($A20,'TABLA DINAMICA PARCIAL 2'!$A$5:$T$772,14,FALSE) -> 0 | Z20: =VLOOKUP($A20,'TABLA DINAMICA PARCIAL 2'!$A$5:$T$772,15,FALSE) -> 0 | AA20: =VLOOKUP($A20,'TABLA DINAMICA PARCIAL 2'!$A$5:$T$772,16,FALSE) -> 0 | AB20: =VLOOKUP(I20,'TABLA DINAMICA PARCIAL 2'!I815:AB1586,17,FALSE) -> #N/A | AC20: =VLOOKUP(I20,'TABLA DINAMICA PARCIAL 2'!I815:AB1586,18,FALSE) -> #N/A | AD20: =VLOOKUP(I20,'TABLA DINAMICA PARCIAL 2'!I815:AB1586,19,FALSE) -> #N/A | AE20: =SUM(M20:AD20) -> #N/A | AF20: =VLOOKUP($A20,'TABLA DINAMICA PARCIAL 3'!$A$5:$I$768,2,FALSE) -> 10 | AG20: =VLOOKUP($A20,'TABLA DINAMICA PARCIAL 3'!$A$5:$I$768,3,FALSE) -> 0 | AH20: =VLOOKUP($A20,'TABLA DINAMICA PARCIAL 3'!$A$5:$I$768,4,FALSE) -> 10 | AI20: =VLOOKUP($A20,'TABLA DINAMICA PARCIAL 3'!$A$5:$I$768,5,FALSE) -> 0 | AJ20: =VLOOKUP($A20,'TABLA DINAMICA PARCIAL 3'!$A$5:$I$768,6,FALSE) -> 10 | AK20: =VLOOKUP($A20,'TABLA DINAMICA PARCIAL 3'!$A$5:$I$768,7,FALSE) -> 10 | AL20: =VLOOKUP($A20,'TABLA DINAMICA PARCIAL 3'!$A$5:$I$768,8,FALSE) -> 0 | AM20: =SUM(AF20:AL20) -> 40 | AN20: =VLOOKUP($A20,'TABLA DINAMICA PARCIAL 4'!$A$5:$F$760,2,FALSE) -> 10 | AO20: =VLOOKUP($A20,'TABLA DINAMICA PARCIAL 4'!$A$5:$F$760,3,FALSE) -> 0 | AP20: =VLOOKUP($A20,'TABLA DINAMICA PARCIAL 4'!$A$5:$F$760,4,FALSE) -> 0 | AQ20: =VLOOKUP($A20,'TABLA DINAMICA PARCIAL 4'!$A$5:$F$760,5,FALSE) -> 0 | AR20: =VLOOKUP($A20,'TABLA DINAMICA PARCIAL 4'!$A$5:$F$760,6,FALSE) -> 0 | AS20: =SUM(AN20:AR20) -> 10 | AT20: =VLOOKUP($A20,'USUARIOS Y GRUPO'!$A$2:$D$851,4,FALSE) -> P19-MAT1022-10
A21: 162496 | B21: López López | C21: Fernando | D21: =VLOOKUP($A21,'TABLA DINAM PARCIAL 1'!$A$5:$I$793,2,FALSE) -> 0 | E21: =VLOOKUP(A21,'TABLA DINAM PARCIAL 1'!A221:I1009,3,FALSE) -> 10 | F21: =VLOOKUP(A21,'TABLA DINAM PARCIAL 1'!A221:I1009,4,FALSE) -> 0 | G21: =VLOOKUP(A21,'TABLA DINAM PARCIAL 1'!A221:I1009,5,FALSE) -> 0 | H21: =VLOOKUP(A21,'TABLA DINAM PARCIAL 1'!A221:I1009,6,FALSE) -> 10 | I21: =VLOOKUP(A21,'TABLA DINAM PARCIAL 1'!A221:I1009,7,FALSE) -> 0 | J21: =VLOOKUP(A21,'TABLA DINAM PARCIAL 1'!A221:I1009,8,FALSE) -> 10 | K21: =VLOOKUP(A21,'TABLA DINAM PARCIAL 1'!A221:I1009,9,FALSE) -> 0 | L21: =SUM(D21:K21) -> 30 | M21: =VLOOKUP($A21,'TABLA DINAMICA PARCIAL 2'!$A$5:$T$772,2,FALSE) -> 0 | N21: =VLOOKUP($A21,'TABLA DINAMICA PARCIAL 2'!$A$5:$T$772,3,FALSE) -> 0 | O21: =VLOOKUP($A21,'TABLA DINAMICA PARCIAL 2'!$A$5:$T$772,4,FALSE) -> 0 | P21: =VLOOKUP($A21,'TABLA DINAMICA PARCIAL 2'!$A$5:$T$772,5,FALSE) -> 0 | Q21: =VLOOKUP($A21,'TABLA DINAMICA PARCIAL 2'!$A$5:$T$772,6,FALSE) -> 0 | R21: =VLOOKUP($A21,'TABLA DINAMICA PARCIAL 2'!$A$5:$T$772,7,FALSE) -> 0 | S21: =VLOOKUP($A21,'TABLA DINAMICA PARCIAL 2'!$A$5:$T$772,8,FALSE) -> 0 | T21: =VLOOKUP($A21,'TABLA DINAMICA PARCIAL 2'!$A$5:$T$772,9,FALSE) -> 10 | U21: =VLOOKUP($A21,'TABLA DINAMICA PARCIAL 2'!$A$5:$T$772,10,FALSE) -> 0 | V21: =VLOOKUP($A21,'TABLA DINAMICA PARCIAL 2'!$A$5:$T$772,11,FALSE) -> 0 | W21: =VLOOKUP($A21,'TABLA DINAMICA PARCIAL 2'!$A$5:$T$772,12,FALSE) -> 0 | X21: =VLOOKUP($A21,'TABLA DINAMICA PARCIAL 2'!$A$5:$T$772,13,FALSE) -> 0 | Y21: =VLOOKUP($A21,'TABLA DINAMICA PARCIAL 2'!$A$5:$T$772,14,FALSE) -> 0 | Z21: =VLOOKUP($A21,'TABLA DINAMICA PARCIAL 2'!$A$5:$T$772,15,FALSE) -> 0 | AA21: =VLOOKUP($A21,'TABLA DINAMICA PARCIAL 2'!$A$5:$T$772,16,FALSE) -> 0 | AB21: =VLOOKUP(I21,'TABLA DINAMICA PARCIAL 2'!I251:AB1022,17,FALSE) -> 0 | AC21: =VLOOKUP(I21,'TABLA DINAMICA PARCIAL 2'!I251:AB1022,18,FALSE) -> 0 | AD21: =VLOOKUP(I21,'TABLA DINAMICA PARCIAL 2'!I251:AB1022,19,FALSE) -> 0 | AE21: =SUM(M21:AD21) -> 10 | AF21: =VLOOKUP($A21,'TABLA DINAMICA PARCIAL 3'!$A$5:$I$768,2,FALSE) -> 0 | AG21: =VLOOKUP($A21,'TABLA DINAMICA PARCIAL 3'!$A$5:$I$768,3,FALSE) -> 0 | AH21: =VLOOKUP($A21,'TABLA DINAMICA PARCIAL 3'!$A$5:$I$768,4,FALSE) -> 0 | AI21: =VLOOKUP($A21,'TABLA DINAMICA PARCIAL 3'!$A$5:$I$768,5,FALSE) -> 10 | AJ21: =VLOOKUP($A21,'TABLA DINAMICA PARCIAL 3'!$A$5:$I$768,6,FALSE) -> 0 | AK21: =VLOOKUP($A21,'TABLA DINAMICA PARCIAL 3'!$A$5:$I$768,7,FALSE) -> 10 | AL21: =VLOOKUP($A21,'TABLA DINAMICA PARCIAL 3'!$A$5:$I$768,8,FALSE) -> 0 | AM21: =SUM(AF21:AL21) -> 20 | AN21: =VLOOKUP($A21,'TABLA DINAMICA PARCIAL 4'!$A$5:$F$760,2,FALSE) -> 0 | AO21: =VLOOKUP($A21,'TABLA DINAMICA PARCIAL 4'!$A$5:$F$760,3,FALSE) -> 0 | AP21: =VLOOKUP($A21,'TABLA DINAMICA PARCIAL 4'!$A$5:$F$760,4,FALSE) -> 0 | AQ21: =VLOOKUP($A21,'TABLA DINAMICA PARCIAL 4'!$A$5:$F$760,5,FALSE) -> 0 | AR21: =VLOOKUP($A21,'TABLA DINAMICA PARCIAL 4'!$A$5:$F$760,6,FALSE) -> 10 | AS21: =SUM(AN21:AR21) -> 10 | AT21: =VLOOKUP($A21,'USUARIOS Y GRUPO'!$A$2:$D$851,4,FALSE) -> P19-MAT1022-10
