Workbook

Sheet Examen diagnóstico (2)
A1: Apellidos | B1: Nombre | C1: Nombre de usuario | D1: ID | E1: DIAGNÓSTICO 1. CONJUNTOS (G)(1) [Puntos totales: 50 Puntuación] |179315 | F1: DIAGNÓSTICO 2. NÚMEROS (G)(1) [Puntos totales: 40 Puntuación] |179316 | G1: DIAGNÓSTICO 3. SÍMBOLOS ALGEBRAICOS (G)(1) [Puntos totales: 70 Puntuación] |179317 | H1: DIAGNÓSTICO (G1) [Puntos totales: 20 Puntuación] |179223 | I1: DIAGNÓSTICO G3 [Puntos totales: 60 Puntuación] |179224 | J1: DIAGNÓSTICO G2 [Puntos totales: 20 Puntuación] |179225 | K1: DIAGNÓSTICO G4 [Puntos totales: 10 Puntuación] |179226 | L1: DIAGNÓSTICO G5 [Puntos totales: 10 Puntuación] |179227 | M1: RTDG [Puntos totales: hasta 120 Puntuación] |179221 | N1: Control de becarios [Puntos totales: 20 Puntuación] |179314 | O1: RTDGB [Puntos totales: hasta 160 Puntuación] |179318 | P1: Orden o jerarquía de operaciones [Puntos totales: 0 Puntuación] |179319 | Q1: Prueba [Puntos totales: 10 Puntuación] |181213 | R1: Prueba [Puntos totales: 10 Puntuación] |181214 | S1: Examen 160 | T1: Examen 120 | U1: PRESENTÓ | V1: PE 160 | W1: PE 120 | X1: AP 160 | Y1: AP 120 | Z1: CONJUNTOS | AA1: NÚMEROS | AB1: SÍMBOLOS | AC1: DIAGG1 | AD1: DIAGG2 | AE1: DIAGG3 | AF1: DIAGG4 | AG1: DIAGG5
A2: . Beltrán | B2: Xitlaly | C2: 164732 | D2: 164732 | S2: =O2/16 -> 0 | T2: =M2/12 -> 0 | U2: =IF(AND(E2="",F2="",G2="",H2="",I2="",J2="",K2="",L2="",M2=""),0,1) -> 0 | V2: =IF(O2="",0,1) -> 0 | W2: =IF(M2="",0,1) -> 0 | X2: =IF(AND(V2=1,S2>6),1,0) -> 0 | Y2: =IF(AND(W2=1,T2>6),1,0) -> 0 | Z2: =E2/5 -> 0 | AA2: =F2/4 -> 0 | AB2: =G2/7 -> 0 | AC2: =H2/2 -> 0 | AD2: =I2/6 -> 0 | AE2: =J2/2 -> 0 | AF2: =K2 -> 0 | AG2: =L2 -> 0
A3: Abad Muñoz | B3: Andres | C3: 168181 | D3: 168181 | H3: 0 | I3: 40 | J3: 10 | K3: 10 | L3: 0 | M3: 60 | S3: =O3/16 -> 0 | T3: =M3/12 -> 5 | U3: =IF(AND(E3="",F3="",G3="",H3="",I3="",J3="",K3="",L3="",M3=""),0,1) -> 1 | V3: =IF(O3="",0,1) -> 0 | W3: =IF(M3="",0,1) -> 1 | X3: =IF(AND(V3=1,S3>6),1,0) -> 0 | Y3: =IF(AND(W3=1,T3>6),1,0) -> 0 | Z3: =E3/5 -> 0 | AA3: =F3/4 -> 0 | AB3: =G3/7 -> 0 | AC3: =H3/2 -> 0 | AD3: =I3/6 -> 6.6666667 | AE3: =J3/2 -> 5 | AF3: =K3 -> 10 | AG3: =L3 -> 0
A4: Abascal Bernal | B4: Elizabeth | C4: 166769 | D4: 166769 | H4: 20 | I4: 40 | J4: 0 | K4: 10 | L4: 0 | M4: 70 | S4: =O4/16 -> 0 | T4: =M4/12 -> 5.8333333 | U4: =IF(AND(E4="",F4="",G4="",H4="",I4="",J4="",K4="",L4="",M4=""),0,1) -> 1 | V4: =IF(O4="",0,1) -> 0 | W4: =IF(M4="",0,1) -> 1 | X4: =IF(AND(V4=1,S4>6),1,0) -> 0 | Y4: =IF(AND(W4=1,T4>6),1,0) -> 0 | Z4: =E4/5 -> 0 | AA4: =F4/4 -> 0 | AB4: =G4/7 -> 0 | AC4: =H4/2 -> 10 | AD4: =I4/6 -> 6.6666667 | AE4: =J4/2 -> 0 | AF4: =K4 -> 10 | AG4: =L4 -> 0
A5: Abascal Bernal | B5: Maria Jose | C5: 166768 | D5: 166768 | E5: 10 | F5: 10 | G5: 40 | O5: 60 | S5: =O5/16 -> 3.75 | T5: =M5/12 -> 0 | U5: =IF(AND(E5="",F5="",G5="",H5="",I5="",J5="",K5="",L5="",M5=""),0,1) -> 1 | V5: =IF(O5="",0,1) -> 1 | W5: =IF(M5="",0,1) -> 0 | X5: =IF(AND(V5=1,S5>6),1,0) -> 0 | Y5: =IF(AND(W5=1,T5>6),1,0) -> 0 | Z5: =E5/5 -> 2 | AA5: =F5/4 -> 2.5 | AB5: =G5/7 -> 5.7142857 | AC5: =H5/2 -> 0 | AD5: =I5/6 -> 0 | AE5: =J5/2 -> 0 | AF5: =K5 -> 0 | AG5: =L5 -> 0
A6: Abraham Rothlaender | B6: Lucia | C6: 167803 | D6: 167803 | E6: 30 | F6: 20 | G6: 30 | O6: 80 | S6: =O6/16 -> 5 | T6: =M6/12 -> 0 | U6: =IF(AND(E6="",F6="",G6="",H6="",I6="",J6="",K6="",L6="",M6=""),0,1) -> 1 | V6: =IF(O6="",0,1) -> 1 | W6: =IF(M6="",0,1) -> 0 | X6: =IF(AND(V6=1,S6>6),1,0) -> 0 | Y6: =IF(AND(W6=1,T6>6),1,0) -> 0 | Z6: =E6/5 -> 6 | AA6: =F6/4 -> 5 | AB6: =G6/7 -> 4.2857143 | AC6: =H6/2 -> 0 | AD6: =I6/6 -> 0 | AE6: =J6/2 -> 0 | AF6: =K6 -> 0 | AG6: =L6 -> 0
A7: Abrego Osorio | B7: Elizabeth | C7: 166428 | D7: 166428 | E7: 50 | O7: 50 | S7: =O7/16 -> 3.125 | T7: =M7/12 -> 0 | U7: =IF(AND(E7="",F7="",G7="",H7="",I7="",J7="",K7="",L7="",M7=""),0,1) -> 1 | V7: =IF(O7="",0,1) -> 1 | W7: =IF(M7="",0,1) -> 0 | X7: =IF(AND(V7=1,S7>6),1,0) -> 0 | Y7: =IF(AND(W7=1,T7>6),1,0) -> 0 | Z7: =E7/5 -> 10 | AA7: =F7/4 -> 0 | AB7: =G7/7 -> 0 | AC7: =H7/2 -> 0 | AD7: =I7/6 -> 0 | AE7: =J7/2 -> 0 | AF7: =K7 -> 0 | AG7: =L7 -> 0
A8: Aburto Ramos | B8: Marlene | C8: 165299 | D8: 165299 | E8: 30 | F8: 0 | G8: 10 | O8: 40 | S8: =O8/16 -> 2.5 | T8: =M8/12 -> 0 | U8: =IF(AND(E8="",F8="",G8="",H8="",I8="",J8="",K8="",L8="",M8=""),0,1) -> 1 | V8: =IF(O8="",0,1) -> 1 | W8: =IF(M8="",0,1) -> 0 | X8: =IF(AND(V8=1,S8>6),1,0) -> 0 | Y8: =IF(AND(W8=1,T8>6),1,0) -> 0 | Z8: =E8/5 -> 6 | AA8: =F8/4 -> 0 | AB8: =G8/7 -> 1.4285714 | AC8: =H8/2 -> 0 | AD8: =I8/6 -> 0 | AE8: =J8/2 -> 0 | AF8: =K8 -> 0 | AG8: =L8 -> 0
A9: Acevedo Ledo | B9: Flavio Jesús | C9: 168488 | D9: 168488 | E9: 30 | F9: 10 | G9: 40 | O9: 80 | S9: =O9/16 -> 5 | T9: =M9/12 -> 0 | U9: =IF(AND(E9="",F9="",G9="",H9="",I9="",J9="",K9="",L9="",M9=""),0,1) -> 1 | V9: =IF(O9="",0,1) -> 1 | W9: =IF(M9="",0,1) -> 0 | X9: =IF(AND(V9=1,S9>6),1,0) -> 0 | Y9: =IF(AND(W9=1,T9>6),1,0) -> 0 | Z9: =E9/5 -> 6 | AA9: =F9/4 -> 2.5 | AB9: =G9/7 -> 5.7142857 | AC9: =H9/2 -> 0 | AD9: =I9/6 -> 0 | AE9: =J9/2 -> 0 | AF9: =K9 -> 0 | AG9: =L9 -> 0
A10: Acevedo Molina | B10: Luis Carlos | C10: 161869 | D10: 161869 | S10: =O10/16 -> 0 | T10: =M10/12 -> 0 | U10: =IF(AND(E10="",F10="",G10="",H10="",I10="",J10="",K10="",L10="",M10=""),0,1) -> 0 | V10: =IF(O10="",0,1) -> 0 | W10: =IF(M10="",0,1) -> 0 | X10: =IF(AND(V10=1,S10>6),1,0) -> 0 | Y10: =IF(AND(W10=1,T10>6),1,0) -> 0 | Z10: =E10/5 -> 0 | AA10: =F10/4 -> 0 | AB10: =G10/7 -> 0 | AC10: =H10/2 -> 0 | AD10: =I10/6 -> 0 | AE10: =J10/2 -> 0 | AF10: =K10 -> 0 | AG10: =L10 -> 0
A11: Aceves_PreviewUser | B11: Denisse | C11: 21275_previewuser | S11: =O11/16 -> 0 | T11: =M11/12 -> 0 | U11: =IF(AND(E11="",F11="",G11="",H11="",I11="",J11="",K11="",L11="",M11=""),0,1) -> 0 | V11: =IF(O11="",0,1) -> 0 | W11: =IF(M11="",0,1) -> 0 | X11: =IF(AND(V11=1,S11>6),1,0) -> 0 | Y11: =IF(AND(W11=1,T11>6),1,0) -> 0 | Z11: =E11/5 -> 0 | AA11: =F11/4 -> 0 | AB11: =G11/7 -> 0 | AC11: =H11/2 -> 0 | AD11: =I11/6 -> 0 | AE11: =J11/2 -> 0 | AF11: =K11 -> 0 | AG11: =L11 -> 0
A12: Acosta Avila | B12: David André | C12: 166580 | D12: 166580 | H12: 20 | I12: 20 | J12: 20 | K12: 10 | L12: 0 | M12: 70 | S12: =O12/16 -> 0 | T12: =M12/12 -> 5.8333333 | U12: =IF(AND(E12="",F12="",G12="",H12="",I12="",J12="",K12="",L12="",M12=""),0,1) -> 1 | V12: =IF(O12="",0,1) -> 0 | W12: =IF(M12="",0,1) -> 1 | X12: =IF(AND(V12=1,S12>6),1,0) -> 0 | Y12: =IF(AND(W12=1,T12>6),1,0) -> 0 | Z12: =E12/5 -> 0 | AA12: =F12/4 -> 0 | AB12: =G12/7 -> 0 | AC12: =H12/2 -> 10 | AD12: =I12/6 -> 3.3333333 | AE12: =J12/2 -> 10 | AF12: =K12 -> 10 | AG12: =L12 -> 0
A13: Acosta Herrera | B13: Maximo Daniel | C13: 168631 | D13: 168631 | E13: 10 | F13: 10 | G13: 40 | O13: 60 | S13: =O13/16 -> 3.75 | T13: =M13/12 -> 0 | U13: =IF(AND(E13="",F13="",G13="",H13="",I13="",J13="",K13="",L13="",M13=""),0,1) -> 1 | V13: =IF(O13="",0,1) -> 1 | W13: =IF(M13="",0,1) -> 0 | X13: =IF(AND(V13=1,S13>6),1,0) -> 0 | Y13: =IF(AND(W13=1,T13>6),1,0) -> 0 | Z13: =E13/5 -> 2 | AA13: =F13/4 -> 2.5 | AB13: =G13/7 -> 5.7142857 | AC13: =H13/2 -> 0 | AD13: =I13/6 -> 0 | AE13: =J13/2 -> 0 | AF13: =K13 -> 0 | AG13: =L13 -> 0
A14: Affif Téllez | B14: Alejandra | C14: 167152 | D14: 167152 | E14: 10 | F14: 20 | G14: 10 | O14: 40 | S14: =O14/16 -> 2.5 | T14: =M14/12 -> 0 | U14: =IF(AND(E14="",F14="",G14="",H14="",I14="",J14="",K14="",L14="",M14=""),0,1) -> 1 | V14: =IF(O14="",0,1) -> 1 | W14: =IF(M14="",0,1) -> 0 | X14: =IF(AND(V14=1,S14>6),1,0) -> 0 | Y14: =IF(AND(W14=1,T14>6),1,0) -> 0 | Z14: =E14/5 -> 2 | AA14: =F14/4 -> 5 | AB14: =G14/7 -> 1.4285714 | AC14: =H14/2 -> 0 | AD14: =I14/6 -> 0 | AE14: =J14/2 -> 0 | AF14: =K14 -> 0 | AG14: =L14 -> 0
A15: Aguado Siany | B15: Fernando | C15: 167383 | D15: 167383 | E15: 10 | F15: 10 | G15: 50 | O15: 70 | S15: =O15/16 -> 4.375 | T15: =M15/12 -> 0 | U15: =IF(AND(E15="",F15="",G15="",H15="",I15="",J15="",K15="",L15="",M15=""),0,1) -> 1 | V15: =IF(O15="",0,1) -> 1 | W15: =IF(M15="",0,1) -> 0 | X15: =IF(AND(V15=1,S15>6),1,0) -> 0 | Y15: =IF(AND(W15=1,T15>6),1,0) -> 0 | Z15: =E15/5 -> 2 | AA15: =F15/4 -> 2.5 | AB15: =G15/7 -> 7.1428571 | AC15: =H15/2 -> 0 | AD15: =I15/6 -> 0 | AE15: =J15/2 -> 0 | AF15: =K15 -> 0 | AG15: =L15 -> 0
A16: Aguayo Zanoguera | B16: Josué Roberto | C16: 166092 | D16: 166092 | E16: 30 | F16: 20 | G16: 30 | O16: 80 | S16: =O16/16 -> 5 | T16: =M16/12 -> 0 | U16: =IF(AND(E16="",F16="",G16="",H16="",I16="",J16="",K16="",L16="",M16=""),0,1) -> 1 | V16: =IF(O16="",0,1) -> 1 | W16: =IF(M16="",0,1) -> 0 | X16: =IF(AND(V16=1,S16>6),1,0) -> 0 | Y16: =IF(AND(W16=1,T16>6),1,0) -> 0 | Z16: =E16/5 -> 6 | AA16: =F16/4 -> 5 | AB16: =G16/7 -> 4.2857143 | AC16: =H16/2 -> 0 | AD16: =I16/6 -> 0 | AE16: =J16/2 -> 0 | AF16: =K16 -> 0 | AG16: =L16 -> 0
A17: Aguila Guevara | B17: Mariana | C17: 166384 | D17: 166384 | E17: 40 | F17: 10 | G17: 40 | O17: 90 | S17: =O17/16 -> 5.625 | T17: =M17/12 -> 0 | U17: =IF(AND(E17="",F17="",G17="",H17="",I17="",J17="",K17="",L17="",M17=""),0,1) -> 1 | V17: =IF(O17="",0,1) -> 1 | W17: =IF(M17="",0,1) -> 0 | X17: =IF(AND(V17=1,S17>6),1,0) -> 0 | Y17: =IF(AND(W17=1,T17>6),1,0) -> 0 | Z17: =E17/5 -> 8 | AA17: =F17/4 -> 2.5 | AB17: =G17/7 -> 5.7142857 | AC17: =H17/2 -> 0 | AD17: =I17/6 -> 0 | AE17: =J17/2 -> 0 | AF17: =K17 -> 0 | AG17: =L17 -> 0
A18: Aguilar Cepeda | B18: Luis Alejandro | C18: 164706 | D18: 164706 | R18: 0 | S18: =O18/16 -> 0 | T18: =M18/12 -> 0 | U18: =IF(AND(E18="",F18="",G18="",H18="",I18="",J18="",K18="",L18="",M18=""),0,1) -> 0 | V18: =IF(O18="",0,1) -> 0 | W18: =IF(M18="",0,1) -> 0 | X18: =IF(AND(V18=1,S18>6),1,0) -> 0 | Y18: =IF(AND(W18=1,T18>6),1,0) -> 0 | Z18: =E18/5 -> 0 | AA18: =F18/4 -> 0 | AB18: =G18/7 -> 0 | AC18: =H18/2 -> 0 | AD18: =I18/6 -> 0 | AE18: =J18/2 -> 0 | AF18: =K18 -> 0 | AG18: =L18 -> 0
A19: Aguilar Lobato | B19: Ana Karen | C19: 165973 | D19: 165973 | H19: 10 | I19: 10 | J19: 10 | K19: 10 | L19: 0 | M19: 40 | S19: =O19/16 -> 0 | T19: =M19/12 -> 3.3333333 | U19: =IF(AND(E19="",F19="",G19="",H19="",I19="",J19="",K19="",L19="",M19=""),0,1) -> 1 | V19: =IF(O19="",0,1) -> 0 | W19: =IF(M19="",0,1) -> 1 | X19: =IF(AND(V19=1,S19>6),1,0) -> 0 | Y19: =IF(AND(W19=1,T19>6),1,0) -> 0 | Z19: =E19/5 -> 0 | AA19: =F19/4 -> 0 | AB19: =G19/7 -> 0 | AC19: =H19/2 -> 5 | AD19: =I19/6 -> 1.6666667 | AE19: =J19/2 -> 5 | AF19: =K19 -> 10 | AG19: =L19 -> 0
A20: Aguilar Morales | B20: Mariam | C20: 167354 | D20: 167354 | H20: 10 | I20: 40 | J20: 10 | K20: 0 | L20: 0 | M20: 60 | S20: =O20/16 -> 0 | T20: =M20/12 -> 5 | U20: =IF(AND(E20="",F20="",G20="",H20="",I20="",J20="",K20="",L20="",M20=""),0,1) -> 1 | V20: =IF(O20="",0,1) -> 0 | W20: =IF(M20="",0,1) -> 1 | X20: =IF(AND(V20=1,S20>6),1,0) -> 0 | Y20: =IF(AND(W20=1,T20>6),1,0) -> 0 | Z20: =E20/5 -> 0 | AA20: =F20/4 -> 0 | AB20: =G20/7 -> 0 | AC20: =H20/2 -> 5 | AD20: =I20/6 -> 6.6666667 | AE20: =J20/2 -> 5 | AF20: =K20 -> 0 | AG20: =L20 -> 0
A21: Aguilar Paz | B21: Sebastián | C21: 168609 | D21: 168609 | H21: 20 | I21: 30 | J21: 20 | K21: 0 | L21: 10 | M21: 80 | S21: =O21/16 -> 0 | T21: =M21/12 -> 6.6666667 | U21: =IF(AND(E21="",F21="",G21="",H21="",I21="",J21="",K21="",L21="",M21=""),0,1) -> 1 | V21: =IF(O21="",0,1) -> 0 | W21: =IF(M21="",0,1) -> 1 | X21: =IF(AND(V21=1,S21>6),1,0) -> 0 | Y21: =IF(AND(W21=1,T21>6),1,0) -> 1 | Z21: =E21/5 -> 0 | AA21: =F21/4 -> 0 | AB21: =G21/7 -> 0 | AC21: =H21/2 -> 10 | AD21: =I21/6 -> 5 | AE21: =J21/2 -> 10 | AF21: =K21 -> 0 | AG21: =L21 -> 10
A22: Aguilar Salazar | B22: Paulina | C22: 166791 | D22: 166791 | E22: 10 | F22: 10 | G22: 30 | O22: 50 | S22: =O22/16 -> 3.125 | T22: =M22/12 -> 0 | U22: =IF(AND(E22="",F22="",G22="",H22="",I22="",J22="",K22="",L22="",M22=""),0,1) -> 1 | V22: =IF(O22="",0,1) -> 1 | W22: =IF(M22="",0,1) -> 0 | X22: =IF(AND(V22=1,S22>6),1,0) -> 0 | Y22: =IF(AND(W22=1,T22>6),1,0) -> 0 | Z22: =E22/5 -> 2 | AA22: =F22/4 -> 2.5 | AB22: =G22/7 -> 4.2857143 | AC22: =H22/2 -> 0 | AD22: =I22/6 -> 0 | AE22: =J22/2 -> 0 | AF22: =K22 -> 0 | AG22: =L22 -> 0
A23: Aguilera V zquez | B23: Monica | C23: 167553 | D23: 167553 | H23: 10 | I23: 30 | J23: 10 | K23: 10 | L23: 0 | M23: 60 | S23: =O23/16 -> 0 | T23: =M23/12 -> 5 | U23: =IF(AND(E23="",F23="",G23="",H23="",I23="",J23="",K23="",L23="",M23=""),0,1) -> 1 | V23: =IF(O23="",0,1) -> 0 | W23: =IF(M23="",0,1) -> 1 | X23: =IF(AND(V23=1,S23>6),1,0) -> 0 | Y23: =IF(AND(W23=1,T23>6),1,0) -> 0 | Z23: =E23/5 -> 0 | AA23: =F23/4 -> 0 | AB23: =G23/7 -> 0 | AC23: =H23/2 -> 5 | AD23: =I23/6 -> 5 | AE23: =J23/2 -> 5 | AF23: =K23 -> 10 | AG23: =L23 -> 0
A24: Aguirre Gutiérrez | B24: Brenda Elizabeth | C24: 168589 | D24: 168589 | H24: 20 | I24: 50 | J24: 10 | K24: 10 | L24: 10 | M24: 100 | S24: =O24/16 -> 0 | T24: =M24/12 -> 8.3333333 | U24: =IF(AND(E24="",F24="",G24="",H24="",I24="",J24="",K24="",L24="",M24=""),0,1) -> 1 | V24: =IF(O24="",0,1) -> 0 | W24: =IF(M24="",0,1) -> 1 | X24: =IF(AND(V24=1,S24>6),1,0) -> 0 | Y24: =IF(AND(W24=1,T24>6),1,0) -> 1 | Z24: =E24/5 -> 0 | AA24: =F24/4 -> 0 | AB24: =G24/7 -> 0 | AC24: =H24/2 -> 10 | AD24: =I24/6 -> 8.3333333 | AE24: =J24/2 -> 5 | AF24: =K24 -> 10 | AG24: =L24 -> 10
A25: Aguirre Hernández | B25: Ixchel Janice | C25: 167379 | D25: 167379 | S25: =O25/16 -> 0 | T25: =M25/12 -> 0 | U25: =IF(AND(E25="",F25="",G25="",H25="",I25="",J25="",K25="",L25="",M25=""),0,1) -> 0 | V25: =IF(O25="",0,1) -> 0 | W25: =IF(M25="",0,1) -> 0 | X25: =IF(AND(V25=1,S25>6),1,0) -> 0 | Y25: =IF(AND(W25=1,T25>6),1,0) -> 0 | Z25: =E25/5 -> 0 | AA25: =F25/4 -> 0 | AB25: =G25/7 -> 0 | AC25: =H25/2 -> 0 | AD25: =I25/6 -> 0 | AE25: =J25/2 -> 0 | AF25: =K25 -> 0 | AG25: =L25 -> 0
A26: Aguirre Torres | B26: Paola | C26: 167637 | D26: 167637 | E26: 10 | F26: 20 | G26: 20 | O26: 50 | S26: =O26/16 -> 3.125 | T26: =M26/12 -> 0 | U26: =IF(AND(E26="",F26="",G26="",H26="",I26="",J26="",K26="",L26="",M26=""),0,1) -> 1 | V26: =IF(O26="",0,1) -> 1 | W26: =IF(M26="",0,1) -> 0 | X26: =IF(AND(V26=1,S26>6),1,0) -> 0 | Y26: =IF(AND(W26=1,T26>6),1,0) -> 0 | Z26: =E26/5 -> 2 | AA26: =F26/4 -> 5 | AB26: =G26/7 -> 2.8571429 | AC26: =H26/2 -> 0 | AD26: =I26/6 -> 0 | AE26: =J26/2 -> 0 | AF26: =K26 -> 0 | AG26: =L26 -> 0
A27: Agut Cadena | B27: Angélica Paola | C27: 165710 | D27: 165710 | H27: 10 | I27: 40 | J27: 20 | K27: 0 | L27: 10 | M27: 80 | S27: =O27/16 -> 0 | T27: =M27/12 -> 6.6666667 | U27: =IF(AND(E27="",F27="",G27="",H27="",I27="",J27="",K27="",L27="",M27=""),0,1) -> 1 | V27: =IF(O27="",0,1) -> 0 | W27: =IF(M27="",0,1) -> 1 | X27: =IF(AND(V27=1,S27>6),1,0) -> 0 | Y27: =IF(AND(W27=1,T27>6),1,0) -> 1 | Z27: =E27/5 -> 0 | AA27: =F27/4 -> 0 | AB27: =G27/7 -> 0 | AC27: =H27/2 -> 5 | AD27: =I27/6 -> 6.6666667 | AE27: =J27/2 -> 10 | AF27: =K27 -> 0 | AG27: =L27 -> 10
A28: Ahedo Marquez | B28: Raul | C28: 166283 | D28: 166283 | E28: 10 | F28: 10 | G28: 40 | O28: 60 | S28: =O28/16 -> 3.75 | T28: =M28/12 -> 0 | U28: =IF(AND(E28="",F28="",G28="",H28="",I28="",J28="",K28="",L28="",M28=""),0,1) -> 1 | V28: =IF(O28="",0,1) -> 1 | W28: =IF(M28="",0,1) -> 0 | X28: =IF(AND(V28=1,S28>6),1,0) -> 0 | Y28: =IF(AND(W28=1,T28>6),1,0) -> 0 | Z28: =E28/5 -> 2 | AA28: =F28/4 -> 2.5 | AB28: =G28/7 -> 5.7142857 | AC28: =H28/2 -> 0 | AD28: =I28/6 -> 0 | AE28: =J28/2 -> 0 | AF28: =K28 -> 0 | AG28: =L28 -> 0
A29: Ahuactzin Fernández | B29: Antonio Daniel | C29: 164617 | D29: 164617 | H29: 10 | I29: 60 | J29: 10 | K29: 10 | L29: 0 | M29: 90 | S29: =O29/16 -> 0 | T29: =M29/12 -> 7.5 | U29: =IF(AND(E29="",F29="",G29="",H29="",I29="",J29="",K29="",L29="",M29=""),0,1) -> 1 | V29: =IF(O29="",0,1) -> 0 | W29: =IF(M29="",0,1) -> 1 | X29: =IF(AND(V29=1,S29>6),1,0) -> 0 | Y29: =IF(AND(W29=1,T29>6),1,0) -> 1 | Z29: =E29/5 -> 0 | AA29: =F29/4 -> 0 | AB29: =G29/7 -> 0 | AC29: =H29/2 -> 5 | AD29: =I29/6 -> 10 | AE29: =J29/2 -> 5 | AF29: =K29 -> 10 | AG29: =L29 -> 0
A30: Ahumada Vázquez | B30: Fátima | C30: 167514 | D30: 167514 | E30: 20 | F30: 20 | G30: 10 | O30: 50 | S30: =O30/16 -> 3.125 | T30: =M30/12 -> 0 | U30: =IF(AND(E30="",F30="",G30="",H30="",I30="",J30="",K30="",L30="",M30=""),0,1) -> 1 | V30: =IF(O30="",0,1) -> 1 | W30: =IF(M30="",0,1) -> 0 | X30: =IF(AND(V30=1,S30>6),1,0) -> 0 | Y30: =IF(AND(W30=1,T30>6),1,0) -> 0 | Z30: =E30/5 -> 4 | AA30: =F30/4 -> 5 | AB30: =G30/7 -> 1.4285714 | AC30: =H30/2 -> 0 | AD30: =I30/6 -> 0 | AE30: =J30/2 -> 0 | AF30: =K30 -> 0 | AG30: =L30 -> 0
A31: Aizpuru López | B31: Susana | C31: 165900 | D31: 165900 | E31: 50 | F31: 10 | G31: 40 | O31: 100 | S31: =O31/16 -> 6.25 | T31: =M31/12 -> 0 | U31: =IF(AND(E31="",F31="",G31="",H31="",I31="",J31="",K31="",L31="",M31=""),0,1) -> 1 | V31: =IF(O31="",0,1) -> 1 | W31: =IF(M31="",0,1) -> 0 | X31: =IF(AND(V31=1,S31>6),1,0) -> 1 | Y31: =IF(AND(W31=1,T31>6),1,0) -> 0 | Z31: =E31/5 -> 10 | AA31: =F31/4 -> 2.5 | AB31: =G31/7 -> 5.7142857 | AC31: =H31/2 -> 0 | AD31: =I31/6 -> 0 | AE31: =J31/2 -> 0 | AF31: =K31 -> 0 | AG31: =L31 -> 0
A32: Alarcón Gómez | B32: Miguel Angel | C32: 168243 | D32: 168243 | E32: 20 | F32: 20 | G32: 0 | O32: 40 | S32: =O32/16 -> 2.5 | T32: =M32/12 -> 0 | U32: =IF(AND(E32="",F32="",G32="",H32="",I32="",J32="",K32="",L32="",M32=""),0,1) -> 1 | V32: =IF(O32="",0,1) -> 1 | W32: =IF(M32="",0,1) -> 0 | X32: =IF(AND(V32=1,S32>6),1,0) -> 0 | Y32: =IF(AND(W32=1,T32>6),1,0) -> 0 | Z32: =E32/5 -> 4 | AA32: =F32/4 -> 5 | AB32: =G32/7 -> 0 | AC32: =H32/2 -> 0 | AD32: =I32/6 -> 0 | AE32: =J32/2 -> 0 | AF32: =K32 -> 0 | AG32: =L32 -> 0
A33: Alatorre Lopez | B33: Victor Ivan | C33: 164818 | D33: 164818 | H33: 0 | I33: 20 | J33: 10 | K33: 0 | L33: 0 | M33: 30 | S33: =O33/16 -> 0 | T33: =M33/12 -> 2.5 | U33: =IF(AND(E33="",F33="",G33="",H33="",I33="",J33="",K33="",L33="",M33=""),0,1) -> 1 | V33: =IF(O33="",0,1) -> 0 | W33: =IF(M33="",0,1) -> 1 | X33: =IF(AND(V33=1,S33>6),1,0) -> 0 | Y33: =IF(AND(W33=1,T33>6),1,0) -> 0 | Z33: =E33/5 -> 0 | AA33: =F33/4 -> 0 | AB33: =G33/7 -> 0 | AC33: =H33/2 -> 0 | AD33: =I33/6 -> 3.3333333 | AE33: =J33/2 -> 5 | AF33: =K33 -> 0 | AG33: =L33 -> 0
A34: Alcalá Molina | B34: Luis Eduardo | C34: 167696 | D34: 167696 | E34: 0 | F34: 20 | G34: 30 | O34: 50 | S34: =O34/16 -> 3.125 | T34: =M34/12 -> 0 | U34: =IF(AND(E34="",F34="",G34="",H34="",I34="",J34="",K34="",L34="",M34=""),0,1) -> 1 | V34: =IF(O34="",0,1) -> 1 | W34: =IF(M34="",0,1) -> 0 | X34: =IF(AND(V34=1,S34>6),1,0) -> 0 | Y34: =IF(AND(W34=1,T34>6),1,0) -> 0 | Z34: =E34/5 -> 0 | AA34: =F34/4 -> 5 | AB34: =G34/7 -> 4.2857143 | AC34: =H34/2 -> 0 | AD34: =I34/6 -> 0 | AE34: =J34/2 -> 0 | AF34: =K34 -> 0 | AG34: =L34 -> 0
A35: Alcantara Ramírez | B35: Lian Damian | C35: 167115 | D35: 167115 | H35: 20 | I35: 30 | J35: 20 | K35: 0 | L35: 10 | M35: 80 | S35: =O35/16 -> 0 | T35: =M35/12 -> 6.6666667 | U35: =IF(AND(E35="",F35="",G35="",H35="",I35="",J35="",K35="",L35="",M35=""),0,1) -> 1 | V35: =IF(O35="",0,1) -> 0 | W35: =IF(M35="",0,1) -> 1 | X35: =IF(AND(V35=1,S35>6),1,0) -> 0 | Y35: =IF(AND(W35=1,T35>6),1,0) -> 1 | Z35: =E35/5 -> 0 | AA35: =F35/4 -> 0 | AB35: =G35/7 -> 0 | AC35: =H35/2 -> 10 | AD35: =I35/6 -> 5 | AE35: =J35/2 -> 10 | AF35: =K35 -> 0 | AG35: =L35 -> 10
A36: Alcazar Barbosa | B36: Roberto | C36: 166178 | D36: 166178 | H36: 10 | I36: 30 | J36: 20 | K36: 10 | L36: 0 | M36: 70 | S36: =O36/16 -> 0 | T36: =M36/12 -> 5.8333333 | U36: =IF(AND(E36="",F36="",G36="",H36="",I36="",J36="",K36="",L36="",M36=""),0,1) -> 1 | V36: =IF(O36="",0,1) -> 0 | W36: =IF(M36="",0,1) -> 1 | X36: =IF(AND(V36=1,S36>6),1,0) -> 0 | Y36: =IF(AND(W36=1,T36>6),1,0) -> 0 | Z36: =E36/5 -> 0 | AA36: =F36/4 -> 0 | AB36: =G36/7 -> 0 | AC36: =H36/2 -> 5 | AD36: =I36/6 -> 5 | AE36: =J36/2 -> 10 | AF36: =K36 -> 10 | AG36: =L36 -> 0
A37: Alcocer Maldonado | B37: Rogelio Jasef | C37: 168167 | D37: 168167 | E37: 30 | F37: 30 | G37: 40 | O37: 100 | S37: =O37/16 -> 6.25 | T37: =M37/12 -> 0 | U37: =IF(AND(E37="",F37="",G37="",H37="",I37="",J37="",K37="",L37="",M37=""),0,1) -> 1 | V37: =IF(O37="",0,1) -> 1 | W37: =IF(M37="",0,1) -> 0 | X37: =IF(AND(V37=1,S37>6),1,0) -> 1 | Y37: =IF(AND(W37=1,T37>6),1,0) -> 0 | Z37: =E37/5 -> 6 | AA37: =F37/4 -> 7.5 | AB37: =G37/7 -> 5.7142857 | AC37: =H37/2 -> 0 | AD37: =I37/6 -> 0 | AE37: =J37/2 -> 0 | AF37: =K37 -> 0 | AG37: =L37 -> 0
A38: Alcántara Alcántara | B38: Jesús | C38: 168034 | D38: 168034 | S38: =O38/16 -> 0 | T38: =M38/12 -> 0 | U38: =IF(AND(E38="",F38="",G38="",H38="",I38="",J38="",K38="",L38="",M38=""),0,1) -> 0 | V38: =IF(O38="",0,1) -> 0 | W38: =IF(M38="",0,1) -> 0 | X38: =IF(AND(V38=1,S38>6),1,0) -> 0 | Y38: =IF(AND(W38=1,T38>6),1,0) -> 0 | Z38: =E38/5 -> 0 | AA38: =F38/4 -> 0 | AB38: =G38/7 -> 0 | AC38: =H38/2 -> 0 | AD38: =I38/6 -> 0 | AE38: =J38/2 -> 0 | AF38: =K38 -> 0 | AG38: =L38 -> 0
A39: Alcántara De León | B39: Sofía | C39: 163568 | D39: 163568 | E39: 10 | F39: 20 | G39: 30 | O39: 60 | S39: =O39/16 -> 3.75 | T39: =M39/12 -> 0 | U39: =IF(AND(E39="",F39="",G39="",H39="",I39="",J39="",K39="",L39="",M39=""),0,1) -> 1 | V39: =IF(O39="",0,1) -> 1 | W39: =IF(M39="",0,1) -> 0 | X39: =IF(AND(V39=1,S39>6),1,0) -> 0 | Y39: =IF(AND(W39=1,T39>6),1,0) -> 0 | Z39: =E39/5 -> 2 | AA39: =F39/4 -> 5 | AB39: =G39/7 -> 4.2857143 | AC39: =H39/2 -> 0 | AD39: =I39/6 -> 0 | AE39: =J39/2 -> 0 | AF39: =K39 -> 0 | AG39: =L39 -> 0
A40: Alcántara González | B40: María | C40: 168229 | D40: 168229 | S40: =O40/16 -> 0 | T40: =M40/12 -> 0 | U40: =IF(AND(E40="",F40="",G40="",H40="",I40="",J40="",K40="",L40="",M40=""),0,1) -> 0 | V40: =IF(O40="",0,1) -> 0 | W40: =IF(M40="",0,1) -> 0 | X40: =IF(AND(V40=1,S40>6),1,0) -> 0 | Y40: =IF(AND(W40=1,T40>6),1,0) -> 0 | Z40: =E40/5 -> 0 | AA40: =F40/4 -> 0 | AB40: =G40/7 -> 0 | AC40: =H40/2 -> 0 | AD40: =I40/6 -> 0 | AE40: =J40/2 -> 0 | AF40: =K40 -> 0 | AG40: =L40 -> 0
...

Sheet Gráficas
A1: Estudiantes que no presentaron examen | B1: Estudiantes que presentaron el examen | C1: Estudiantes que presentaron el examen 160 | D1: Estudiantes que presentaron el examen 120 | E1: Estudiantes que aprobaron el examen 160 | F1: Estudiantes que aprobaron el examen 120 | G1: Promedio de Conjuntos | H1: Promedio de Números | I1: Promedio de Símbolos Algebraicos | J1: Promedio G1 | K1: Promedio G2 | L1: Promedio G3 | M1: Promedio G4 | N1: Promedio G5
A2: =2107-B2 -> 388 | B2: ='Examen diagnóstico (2)'!U2108 -> 1719 | C2: ='Examen diagnóstico (2)'!V2108 -> 887 | D2: ='Examen diagnóstico (2)'!W2108 -> 832 | E2: ='Examen diagnóstico (2)'!X2108 -> 260 | F2: ='Examen diagnóstico (2)'!Y2108 -> 340 | G2: ='Examen diagnóstico (2)'!Z2108 -> 4596 | H2: ='Examen diagnóstico (2)'!AA2108 -> 4617.5 | I2: ='Examen diagnóstico (2)'!AB2108 -> 3792.8571 | ... N2: ='Examen diagnóstico (2)'!AG2108 -> 3960
A3: =388/2107 -> 0.18414808 | B3: ='Examen diagnóstico (2)'!U2109 -> 0.81623932 | C3: ='Examen diagnóstico (2)'!V2109 -> 0.51599767 | D3: ='Examen diagnóstico (2)'!W2109 -> 0.48400233 | E3: ='Examen diagnóstico (2)'!X2109 -> 0.29312289 | F3: ='Examen diagnóstico (2)'!Y2109 -> 0.40865385 | G3: ='Examen diagnóstico (2)'!Z2109 -> 5.1815107 | H3: ='Examen diagnóstico (2)'!AA2109 -> 5.2057497 | I3: ='Examen diagnóstico (2)'!AB2109 -> 4.2760509 | ... N3: ='Examen diagnóstico (2)'!AG2109 -> 4.7596154
A21: Estudiantes que no aprobaron el examen 160 | B21: =E1 -> Estudiantes que aprobaron el examen 160 | G21: Estudiantes que no aprobaron examen 120 | H21: =F1 -> Estudiantes que aprobaron el examen 120
A22: =C2-B22 -> 627 | B22: =E2 -> 260 | G22: =D2-H22 -> 492 | H22: =F2 -> 340
A39: Promedio de Conjuntos | B39: Promedio de Números | C39: Promedio de Símbolos Algebraicos | D39: Promedio G1 | E39: Promedio G2 | F39: Promedio G3 | G39: Promedio G4 | H39: Promedio G5
A40: 5.1815107 | B40: 5.2057497 | C40: 4.2760509 | D40: 5.1442308 | E40: 5.7051282 | F40: 6.2139423 | G40: 6.4903846 | H40: 4.7596154

Sheet Examen diagnóstico
A1: Apellidos | B1: Nombre | C1: Nombre de usuario | D1: ID de alumno | E1: DIAGNÓSTICO 1. CONJUNTOS (G)(1) [Puntos totales: 50 Puntuación] |179315 | F1: DIAGNÓSTICO 2. NÚMEROS (G)(1) [Puntos totales: 40 Puntuación] |179316 | G1: DIAGNÓSTICO 3. SÍMBOLOS ALGEBRAICOS (G)(1) [Puntos totales: 70 Puntuación] |179317 | H1: DIAGNÓSTICO (G1) [Puntos totales: 20 Puntuación] |179223 | I1: DIAGNÓSTICO G3 [Puntos totales: 60 Puntuación] |179224 | J1: DIAGNÓSTICO G2 [Puntos totales: 20 Puntuación] |179225 | K1: DIAGNÓSTICO G4 [Puntos totales: 10 Puntuación] |179226 | L1: DIAGNÓSTICO G5 [Puntos totales: 10 Puntuación] |179227 | M1: RTDG [Puntos totales: hasta 120 Puntuación] |179221 | N1: Control de becarios [Puntos totales: 20 Puntuación] |179314 | O1: RTDGB [Puntos totales: hasta 160 Puntuación] |179318 | P1: Orden o jerarquía de operaciones [Puntos totales: 0 Puntuación] |179319 | Q1: Prueba [Puntos totales: 10 Puntuación] |181213 | R1: Prueba [Puntos totales: 10 Puntuación] |181214
A2: . Beltrán | B2: Xitlaly | C2: 164732 | D2: 164732 | R2: En proceso
A3: Abad Muñoz | B3: Andres | C3: 168181 | D3: 168181 | H3: 0 | I3: 40 | J3: 10 | K3: 10 | L3: 0 | M3: 60
A4: Abascal Bernal | B4: Elizabeth | C4: 166769 | D4: 166769 | H4: 20 | I4: 40 | J4: 0 | K4: 10 | L4: 0 | M4: 70
A5: Abascal Bernal | B5: Maria Jose | C5: 166768 | D5: 166768 | E5: 10 | F5: 10 | G5: 40 | O5: 60
A6: Abraham Rothlaender | B6: Lucia | C6: 167803 | D6: 167803 | E6: 30 | F6: 20 | G6: 30 | O6: 80
A7: Abrego Osorio | B7: Elizabeth | C7: 166428 | D7: 166428 | E7: 50 | O7: 50
A8: Aburto Ramos | B8: Marlene | C8: 165299 | D8: 165299 | E8: 30 | F8: 0 | G8: 10 | O8: 40
A9: Acevedo Ledo | B9: Flavio Jesús | C9: 168488 | D9: 168488 | E9: 30 | F9: 10 | G9: 40 | O9: 80
A10: Acevedo Molina | B10: Luis Carlos | C10: 161869 | D10: 161869
A11: Aceves_PreviewUser | B11: Denisse | C11: 21275_previewuser
A12: Acosta Avila | B12: David André | C12: 166580 | D12: 166580 | H12: 20 | I12: 20 | J12: 20 | K12: 10 | L12: 0 | M12: 70
A13: Acosta Herrera | B13: Maximo Daniel | C13: 168631 | D13: 168631 | E13: 10 | F13: 10 | G13: 40 | O13: 60
A14: Affif Téllez | B14: Alejandra | C14: 167152 | D14: 167152 | E14: 10 | F14: 20 | G14: 10 | O14: 40
A15: Aguado Siany | B15: Fernando | C15: 167383 | D15: 167383 | E15: 10 | F15: 10 | G15: 50 | O15: 70
A16: Aguayo Zanoguera | B16: Josué Roberto | C16: 166092 | D16: 166092 | E16: 30 | F16: 20 | G16: 30 | O16: 80
A17: Aguila Guevara | B17: Mariana | C17: 166384 | D17: 166384 | E17: 40 | F17: 10 | G17: 40 | O17: 90
A18: Aguilar Cepeda | B18: Luis Alejandro | C18: 164706 | D18: 164706 | R18: 0
A19: Aguilar Lobato | B19: Ana Karen | C19: 165973 | D19: 165973 | H19: 10 | I19: 10 | J19: 10 | K19: 10 | L19: 0 | M19: 40
A20: Aguilar Morales | B20: Mariam | C20: 167354 | D20: 167354 | H20: 10 | I20: 40 | J20: 10 | K20: 0 | L20: 0 | M20: 60
A21: Aguilar Paz | B21: Sebastián | C21: 168609 | D21: 168609 | H21: 20 | I21: 30 | J21: 20 | K21: 0 | L21: 10 | M21: 80
A22: Aguilar Salazar | B22: Paulina | C22: 166791 | D22: 166791 | E22: 10 | F22: 10 | G22: 30 | O22: 50
A23: Aguilera V zquez | B23: Monica | C23: 167553 | D23: 167553 | H23: 10 | I23: 30 | J23: 10 | K23: 10 | L23: 0 | M23: 60
A24: Aguirre Gutiérrez | B24: Brenda Elizabeth | C24: 168589 | D24: 168589 | H24: 20 | I24: 50 | J24: 10 | K24: 10 | L24: 10 | M24: 100
A25: Aguirre Hernández | B25: Ixchel Janice | C25: 167379 | D25: 167379
A26: Aguirre Torres | B26: Paola | C26: 167637 | D26: 167637 | E26: 10 | F26: 20 | G26: 20 | O26: 50
A27: Agut Cadena | B27: Angélica Paola | C27: 165710 | D27: 165710 | H27: 10 | I27: 40 | J27: 20 | K27: 0 | L27: 10 | M27: 80
A28: Ahedo Marquez | B28: Raul | C28: 166283 | D28: 166283 | E28: 10 | F28: 10 | G28: 40 | O28: 60
A29: Ahuactzin Fernández | B29: Antonio Daniel | C29: 164617 | D29: 164617 | H29: 10 | I29: 60 | J29: 10 | K29: 10 | L29: 0 | M29: 90
A30: Ahumada Vázquez | B30: Fátima | C30: 167514 | D30: 167514 | E30: 20 | F30: 20 | G30: 10 | O30: 50
A31: Aizpuru López | B31: Susana | C31: 165900 | D31: 165900 | E31: 50 | F31: 10 | G31: 40 | O31: 100
A32: Alarcón Gómez | B32: Miguel Angel | C32: 168243 | D32: 168243 | E32: 20 | F32: 20 | G32: 0 | O32: 40
A33: Alatorre Lopez | B33: Victor Ivan | C33: 164818 | D33: 164818 | H33: 0 | I33: 20 | J33: 10 | K33: 0 | L33: 0 | M33: 30
A34: Alcalá Molina | B34: Luis Eduardo | C34: 167696 | D34: 167696 | E34: 0 | F34: 20 | G34: 30 | O34: 50
A35: Alcantara Ramírez | B35: Lian Damian | C35: 167115 | D35: 167115 | H35: 20 | I35: 30 | J35: 20 | K35: 0 | L35: 10 | M35: 80
A36: Alcazar Barbosa | B36: Roberto | C36: 166178 | D36: 166178 | H36: 10 | I36: 30 | J36: 20 | K36: 10 | L36: 0 | M36: 70
A37: Alcocer Maldonado | B37: Rogelio Jasef | C37: 168167 | D37: 168167 | E37: 30 | F37: 30 | G37: 40 | O37: 100
A38: Alcántara Alcántara | B38: Jesús | C38: 168034 | D38: 168034
A39: Alcántara De León | B39: Sofía | C39: 163568 | D39: 163568 | E39: 10 | F39: 20 | G39: 30 | O39: 60
A40: Alcántara González | B40: María | C40: 168229 | D40: 168229
...
